{
    "registryname": "machine2",
    "localizedname": "大型冶炼厂",
	"requires-blueprint": true,
	"color":"808080",
    "parts": [
        {
            "x": 4,
            "y": 8,
            "z": 4,
            "elements": [
                "extrautils2:decorativesolid@3"
            ]
        },
        {
            "x": -4,
            "y": 0,
            "z": 0,
            "elements": [
                "extrautils2:decorativesolid@3"
            ]
        },
        {
            "x": 4,
            "y": 0,
            "z": 0,
            "elements": [
                "extrautils2:decorativesolid@3"
            ]
        },
        {
            "x": -7,
            "y": 0,
            "z": 0,
            "elements": [
                "minecraft:concrete@0"
            ]
        },
        {
            "x": -8,
            "y": 0,
            "z": 0,
            "elements": [
                "minecraft:concrete@0"
            ]
        },
        {
            "x": -9,
            "y": 0,
            "z": 0,
            "elements": [
                "minecraft:concrete@0"
            ]
        },
        {
            "x": -10,
            "y": 0,
            "z": 0,
            "elements": [
                "minecraft:concrete@0"
            ]
        },
        {
            "x": -11,
            "y": 0,
            "z": 0,
            "elements": [
                "minecraft:concrete@0"
            ]
        },
        {
            "x": -12,
            "y": 0,
            "z": 0,
            "elements": [
                "minecraft:concrete@0"
            ]
        },
        {
            "x": -4,
            "y": 2,
            "z": 17,
            "elements": [
                "skyresources:petrifiedplanks@0"
            ]
        },
        {
            "x": -13,
            "y": 0,
            "z": 0,
            "elements": [
                "minecraft:concrete@0"
            ]
        },
        {
            "x": -14,
            "y": 0,
            "z": 0,
            "elements": [
                "minecraft:concrete@0"
            ]
        },
        {
            "x": -15,
            "y": 0,
            "z": 0,
            "elements": [
                "minecraft:concrete@0"
            ]
        },
        {
            "x": -15,
            "y": 1,
            "z": 0,
            "elements": [
                "minecraft:concrete@0"
            ]
        },
        {
            "x": 4,
            "y": 2,
            "z": 17,
            "elements": [
                "skyresources:petrifiedplanks@0"
            ]
        },
        {
            "x": -4,
            "y": 9,
            "z": 4,
            "elements": [
                "extrautils2:decorativesolid@3"
            ]
        },
        {
            "x": -7,
            "y": 1,
            "z": 0,
            "elements": [
                "minecraft:concrete@0"
            ]
        },
        {
            "x": -3,
            "y": 9,
            "z": 4,
            "elements": [
                "extrautils2:decorativesolid@3"
            ]
        },
        {
            "x": -2,
            "y": 9,
            "z": 4,
            "elements": [
                "extrautils2:decorativesolid@3"
            ]
        },
        {
            "x": -1,
            "y": 9,
            "z": 4,
            "elements": [
                "extrautils2:decorativesolid@3"
            ]
        },
        {
            "x": 4,
            "y": -1,
            "z": 0,
            "elements": [
                "tconstruct:seared@0"
            ]
        },
        {
            "x": 0,
            "y": 9,
            "z": 4,
            "elements": [
                "extrautils2:decorativesolid@3"
            ]
        },
        {
            "x": 3,
            "y": -1,
            "z": 0,
            "elements": [
                "tconstruct:seared@0"
            ]
        },
        {
            "x": -4,
            "y": 1,
            "z": 0,
            "elements": [
                "extrautils2:decorativesolid@3"
            ]
        },
        {
            "x": 1,
            "y": 9,
            "z": 4,
            "elements": [
                "extrautils2:decorativesolid@3"
            ]
        },
        {
            "x": 2,
            "y": -1,
            "z": 0,
            "elements": [
                "tconstruct:seared@0"
            ]
        },
        {
            "x": 1,
            "y": -1,
            "z": 0,
            "elements": [
                "tconstruct:seared@0"
            ]
        },
        {
            "x": 2,
            "y": 9,
            "z": 4,
            "elements": [
                "extrautils2:decorativesolid@3"
            ]
        },
        {
            "x": 0,
            "y": -1,
            "z": 0,
            "elements": [
                "tconstruct:seared@0"
            ]
        },
        {
            "x": -1,
            "y": 1,
            "z": 0,
            "elements": [
                "extrautils2:decorativesolid@3"
            ]
        },
        {
            "x": 3,
            "y": 9,
            "z": 4,
            "elements": [
                "extrautils2:decorativesolid@3"
            ]
        },
        {
            "x": 4,
            "y": 9,
            "z": 4,
            "elements": [
                "extrautils2:decorativesolid@3"
            ]
        },
        {
            "x": 0,
            "y": 1,
            "z": 0,
            "elements": [
                "extrautils2:decorativesolid@3"
            ]
        },
        {
            "x": -1,
            "y": -1,
            "z": 0,
            "elements": [
                "tconstruct:seared@0"
            ]
        },
        {
            "x": 1,
            "y": 1,
            "z": 0,
            "elements": [
                "extrautils2:decorativesolid@3"
            ]
        },
        {
            "x": -2,
            "y": -1,
            "z": 0,
            "elements": [
                "tconstruct:seared@0"
            ]
        },
        {
            "x": -3,
            "y": -1,
            "z": 0,
            "elements": [
                "tconstruct:seared@0"
            ]
        },
        {
            "x": -4,
            "y": -1,
            "z": 0,
            "elements": [
                "tconstruct:seared@0"
            ]
        },
        {
            "x": -5,
            "y": -1,
            "z": 0,
            "elements": [
                "tconstruct:seared@0"
            ]
        },
        {
            "x": 4,
            "y": 1,
            "z": 0,
            "elements": [
                "extrautils2:decorativesolid@3"
            ]
        },
        {
            "x": -6,
            "y": -1,
            "z": 0,
            "elements": [
                "tconstruct:seared@0"
            ]
        },
        {
            "x": -7,
            "y": -1,
            "z": 0,
            "elements": [
                "tconstruct:seared@0"
            ]
        },
        {
            "x": -8,
            "y": -1,
            "z": 0,
            "elements": [
                "tconstruct:seared@0"
            ]
        },
        {
            "x": -9,
            "y": -1,
            "z": 0,
            "elements": [
                "tconstruct:seared@0"
            ]
        },
        {
            "x": -10,
            "y": -1,
            "z": 0,
            "elements": [
                "tconstruct:seared@0"
            ]
        },
        {
            "x": -11,
            "y": -1,
            "z": 0,
            "elements": [
                "tconstruct:seared@0"
            ]
        },
        {
            "x": -12,
            "y": -1,
            "z": 0,
            "elements": [
                "tconstruct:seared@0"
            ]
        },
        {
            "x": -4,
            "y": 3,
            "z": 17,
            "elements": [
                "skyresources:petrifiedplanks@0"
            ]
        },
        {
            "x": -13,
            "y": -1,
            "z": 0,
            "elements": [
                "tconstruct:seared@0"
            ]
        },
        {
            "x": -14,
            "y": -1,
            "z": 0,
            "elements": [
                "tconstruct:seared@0"
            ]
        },
        {
            "x": -15,
            "y": -1,
            "z": 0,
            "elements": [
                "tconstruct:seared@0"
            ]
        },
        {
            "x": -16,
            "y": -1,
            "z": 0,
            "elements": [
                "tconstruct:seared@0"
            ]
        },
        {
            "x": -15,
            "y": 2,
            "z": 0,
            "elements": [
                "minecraft:concrete@0"
            ]
        },
        {
            "x": 4,
            "y": 3,
            "z": 17,
            "elements": [
                "skyresources:petrifiedplanks@0"
            ]
        },
        {
            "x": -7,
            "y": 2,
            "z": 0,
            "elements": [
                "minecraft:concrete@0"
            ]
        },
        {
            "x": -4,
            "y": 2,
            "z": 0,
            "elements": [
                "extrautils2:decorativesolid@3"
            ]
        },
        {
            "x": -2,
            "y": 2,
            "z": 0,
            "elements": [
                "extrautils2:decorativesolid@3"
            ]
        },
        {
            "x": -1,
            "y": 2,
            "z": 0,
            "elements": [
                "extrautils2:decorativesolid@3"
            ]
        },
        {
            "x": 0,
            "y": 2,
            "z": 0,
            "elements": [
                "extrautils2:decorativesolid@3"
            ]
        },
        {
            "x": 1,
            "y": 2,
            "z": 0,
            "elements": [
                "extrautils2:decorativesolid@3"
            ]
        },
        {
            "x": 2,
            "y": 2,
            "z": 0,
            "elements": [
                "extrautils2:decorativesolid@3"
            ]
        },
        {
            "x": 4,
            "y": 2,
            "z": 0,
            "elements": [
                "extrautils2:decorativesolid@3"
            ]
        },
        {
            "x": -4,
            "y": 4,
            "z": 17,
            "elements": [
                "skyresources:petrifiedplanks@0"
            ]
        },
        {
            "x": -15,
            "y": 3,
            "z": 0,
            "elements": [
                "minecraft:concrete@0"
            ]
        },
        {
            "x": -11,
            "y": 11,
            "z": 4,
            "elements": [
                "magneticraft:pneumatic_tube@0"
            ]
        },
        {
            "x": 4,
            "y": 4,
            "z": 17,
            "elements": [
                "skyresources:petrifiedplanks@0"
            ]
        },
        {
            "x": -7,
            "y": 3,
            "z": 0,
            "elements": [
                "minecraft:concrete@0"
            ]
        },
        {
            "x": 0,
            "y": 11,
            "z": 4,
            "elements": [
                "magneticraft:pneumatic_tube@0"
            ]
        },
        {
            "x": -4,
            "y": 3,
            "z": 0,
            "elements": [
                "extrautils2:decorativesolid@3"
            ]
        },
        {
            "x": -3,
            "y": 3,
            "z": 0,
            "elements": [
                "extrautils2:decorativesolid@3"
            ]
        },
        {
            "x": -2,
            "y": 3,
            "z": 0,
            "elements": [
                "extrautils2:decorativesolid@3"
            ]
        },
        {
            "x": -1,
            "y": 3,
            "z": 0,
            "elements": [
                "extrautils2:decorativesolid@3"
            ]
        },
        {
            "x": 0,
            "y": 3,
            "z": 0,
            "elements": [
                "extrautils2:decorativesolid@3"
            ]
        },
        {
            "x": 1,
            "y": 3,
            "z": 0,
            "elements": [
                "extrautils2:decorativesolid@3"
            ]
        },
        {
            "x": 2,
            "y": 3,
            "z": 0,
            "elements": [
                "extrautils2:decorativesolid@3"
            ]
        },
        {
            "x": 3,
            "y": 3,
            "z": 0,
            "elements": [
                "extrautils2:decorativesolid@3"
            ]
        },
        {
            "x": 4,
            "y": 3,
            "z": 0,
            "elements": [
                "extrautils2:decorativesolid@3"
            ]
        },
        {
            "x": -4,
            "y": 5,
            "z": 17,
            "elements": [
                "skyresources:petrifiedplanks@0"
            ]
        },
        {
            "x": -15,
            "y": 4,
            "z": 0,
            "elements": [
                "minecraft:concrete@15"
            ]
        },
        {
            "x": 4,
            "y": 5,
            "z": 17,
            "elements": [
                "skyresources:petrifiedplanks@0"
            ]
        },
        {
            "x": -7,
            "y": 4,
            "z": 0,
            "elements": [
                "minecraft:concrete@15"
            ]
        },
        {
            "x": -4,
            "y": 4,
            "z": 0,
            "elements": [
                "extrautils2:decorativesolid@3"
            ]
        },
        {
            "x": 4,
            "y": 4,
            "z": 0,
            "elements": [
                "extrautils2:decorativesolid@3"
            ]
        },
        {
            "x": -4,
            "y": 6,
            "z": 17,
            "elements": [
                "skyresources:petrifiedplanks@0"
            ]
        },
        {
            "x": -15,
            "y": 5,
            "z": 0,
            "elements": [
                "minecraft:concrete@4"
            ]
        },
        {
            "x": 4,
            "y": 6,
            "z": 17,
            "elements": [
                "skyresources:petrifiedplanks@0"
            ]
        },
        {
            "x": -7,
            "y": 5,
            "z": 0,
            "elements": [
                "minecraft:concrete@4"
            ]
        },
        {
            "x": -4,
            "y": 5,
            "z": 0,
            "elements": [
                "extrautils2:decorativesolid@3"
            ]
        },
        {
            "x": -16,
            "y": -1,
            "z": 13,
            "elements": [
                "tconstruct:seared@0"
            ]
        },
        {
            "x": -15,
            "y": -1,
            "z": 13,
            "elements": [
                "tconstruct:seared@0"
            ]
        },
        {
            "x": 4,
            "y": 5,
            "z": 0,
            "elements": [
                "extrautils2:decorativesolid@3"
            ]
        },
        {
            "x": -14,
            "y": -1,
            "z": 13,
            "elements": [
                "tconstruct:seared@0"
            ]
        },
        {
            "x": -13,
            "y": -1,
            "z": 13,
            "elements": [
                "tconstruct:seared@0"
            ]
        },
        {
            "x": -12,
            "y": -1,
            "z": 13,
            "elements": [
                "tconstruct:seared@0"
            ]
        },
        {
            "x": -11,
            "y": -1,
            "z": 13,
            "elements": [
                "tconstruct:seared@0"
            ]
        },
        {
            "x": -10,
            "y": -1,
            "z": 13,
            "elements": [
                "tconstruct:seared@0"
            ]
        },
        {
            "x": -9,
            "y": -1,
            "z": 13,
            "elements": [
                "tconstruct:seared@0"
            ]
        },
        {
            "x": -8,
            "y": -1,
            "z": 13,
            "elements": [
                "tconstruct:seared@0"
            ]
        },
        {
            "x": -4,
            "y": 7,
            "z": 17,
            "elements": [
                "skyresources:petrifiedplanks@0"
            ]
        },
        {
            "x": -7,
            "y": -1,
            "z": 13,
            "elements": [
                "tconstruct:seared@0"
            ]
        },
        {
            "x": -6,
            "y": -1,
            "z": 13,
            "elements": [
                "tconstruct:seared@0"
            ]
        },
        {
            "x": -5,
            "y": -1,
            "z": 13,
            "elements": [
                "tconstruct:seared@0"
            ]
        },
        {
            "x": -4,
            "y": -1,
            "z": 13,
            "elements": [
                "tconstruct:seared@0"
            ]
        },
        {
            "x": -15,
            "y": 6,
            "z": 0,
            "elements": [
                "minecraft:concrete@15"
            ]
        },
        {
            "x": -3,
            "y": -1,
            "z": 13,
            "elements": [
                "tconstruct:seared@0"
            ]
        },
        {
            "x": -2,
            "y": -1,
            "z": 13,
            "elements": [
                "tconstruct:seared@0"
            ]
        },
        {
            "x": -1,
            "y": -1,
            "z": 13,
            "elements": [
                "tconstruct:seared@0"
            ]
        },
        {
            "x": 0,
            "y": -1,
            "z": 13,
            "elements": [
                "tconstruct:seared@0"
            ]
        },
        {
            "x": 4,
            "y": 7,
            "z": 17,
            "elements": [
                "skyresources:petrifiedplanks@0"
            ]
        },
        {
            "x": 1,
            "y": -1,
            "z": 13,
            "elements": [
                "tconstruct:seared@0"
            ]
        },
        {
            "x": 2,
            "y": -1,
            "z": 13,
            "elements": [
                "tconstruct:seared@0"
            ]
        },
        {
            "x": 3,
            "y": -1,
            "z": 13,
            "elements": [
                "tconstruct:seared@0"
            ]
        },
        {
            "x": 4,
            "y": -1,
            "z": 13,
            "elements": [
                "tconstruct:seared@0"
            ]
        },
        {
            "x": -7,
            "y": 6,
            "z": 0,
            "elements": [
                "minecraft:concrete@15"
            ]
        },
        {
            "x": -4,
            "y": 6,
            "z": 0,
            "elements": [
                "extrautils2:decorativesolid@3"
            ]
        },
        {
            "x": 4,
            "y": 6,
            "z": 0,
            "elements": [
                "extrautils2:decorativesolid@3"
            ]
        },
        {
            "x": -4,
            "y": 8,
            "z": 17,
            "elements": [
                "skyresources:petrifiedplanks@0"
            ]
        },
        {
            "x": -15,
            "y": 7,
            "z": 0,
            "elements": [
                "minecraft:concrete@0"
            ]
        },
        {
            "x": 4,
            "y": 8,
            "z": 17,
            "elements": [
                "skyresources:petrifiedplanks@0"
            ]
        },
        {
            "x": -7,
            "y": 7,
            "z": 0,
            "elements": [
                "minecraft:concrete@0"
            ]
        },
        {
            "x": -4,
            "y": 7,
            "z": 0,
            "elements": [
                "extrautils2:decorativesolid@3"
            ]
        },
        {
            "x": 4,
            "y": 7,
            "z": 0,
            "elements": [
                "extrautils2:decorativesolid@3"
            ]
        },
        {
            "x": -4,
            "y": 9,
            "z": 17,
            "elements": [
                "skyresources:petrifiedplanks@0"
            ]
        },
        {
            "x": -3,
            "y": 9,
            "z": 17,
            "elements": [
                "skyresources:petrifiedplanks@0"
            ]
        },
        {
            "x": -2,
            "y": 9,
            "z": 17,
            "elements": [
                "skyresources:petrifiedplanks@0"
            ]
        },
        {
            "x": -1,
            "y": 9,
            "z": 17,
            "elements": [
                "skyresources:petrifiedplanks@0"
            ]
        },
        {
            "x": 0,
            "y": 9,
            "z": 17,
            "elements": [
                "skyresources:petrifiedplanks@0"
            ]
        },
        {
            "x": 1,
            "y": 9,
            "z": 17,
            "elements": [
                "skyresources:petrifiedplanks@0"
            ]
        },
        {
            "x": -15,
            "y": 8,
            "z": 0,
            "elements": [
                "minecraft:concrete@0"
            ]
        },
        {
            "x": 2,
            "y": 9,
            "z": 17,
            "elements": [
                "skyresources:petrifiedplanks@0"
            ]
        },
        {
            "x": 3,
            "y": 9,
            "z": 17,
            "elements": [
                "skyresources:petrifiedplanks@0"
            ]
        },
        {
            "x": 4,
            "y": 9,
            "z": 17,
            "elements": [
                "skyresources:petrifiedplanks@0"
            ]
        },
        {
            "x": -7,
            "y": 8,
            "z": 0,
            "elements": [
                "minecraft:concrete@0"
            ]
        },
        {
            "x": -4,
            "y": 8,
            "z": 0,
            "elements": [
                "extrautils2:decorativesolid@3"
            ]
        },
        {
            "x": 4,
            "y": 8,
            "z": 0,
            "elements": [
                "extrautils2:decorativesolid@3"
            ]
        },
        {
            "x": -15,
            "y": 9,
            "z": 0,
            "elements": [
                "minecraft:concrete@0"
            ]
        },
        {
            "x": -14,
            "y": 9,
            "z": 0,
            "elements": [
                "minecraft:concrete@0"
            ]
        },
        {
            "x": -13,
            "y": 9,
            "z": 0,
            "elements": [
                "minecraft:concrete@0"
            ]
        },
        {
            "x": -12,
            "y": 9,
            "z": 0,
            "elements": [
                "minecraft:concrete@0"
            ]
        },
        {
            "x": -11,
            "y": 9,
            "z": 0,
            "elements": [
                "minecraft:concrete@0"
            ]
        },
        {
            "x": -10,
            "y": 9,
            "z": 0,
            "elements": [
                "minecraft:concrete@0"
            ]
        },
        {
            "x": -9,
            "y": 9,
            "z": 0,
            "elements": [
                "minecraft:concrete@0"
            ]
        },
        {
            "x": -8,
            "y": 9,
            "z": 0,
            "elements": [
                "minecraft:concrete@0"
            ]
        },
        {
            "x": -7,
            "y": 9,
            "z": 0,
            "elements": [
                "minecraft:concrete@0"
            ]
        },
        {
            "x": -4,
            "y": 9,
            "z": 0,
            "elements": [
                "extrautils2:decorativesolid@3"
            ]
        },
        {
            "x": -3,
            "y": 9,
            "z": 0,
            "elements": [
                "extrautils2:decorativesolid@3"
            ]
        },
        {
            "x": -2,
            "y": 9,
            "z": 0,
            "elements": [
                "extrautils2:decorativesolid@3"
            ]
        },
        {
            "x": -1,
            "y": 9,
            "z": 0,
            "elements": [
                "extrautils2:decorativesolid@3"
            ]
        },
        {
            "x": 0,
            "y": 9,
            "z": 0,
            "elements": [
                "extrautils2:decorativesolid@3"
            ]
        },
        {
            "x": 1,
            "y": 9,
            "z": 0,
            "elements": [
                "extrautils2:decorativesolid@3"
            ]
        },
        {
            "x": 2,
            "y": 9,
            "z": 0,
            "elements": [
                "extrautils2:decorativesolid@3"
            ]
        },
        {
            "x": 3,
            "y": 9,
            "z": 0,
            "elements": [
                "extrautils2:decorativesolid@3"
            ]
        },
        {
            "x": 4,
            "y": 9,
            "z": 0,
            "elements": [
                "extrautils2:decorativesolid@3"
            ]
        },
        {
            "x": 0,
            "y": 11,
            "z": 17,
            "elements": [
                "magneticraft:pneumatic_tube@0"
            ]
        },
        {
            "x": -11,
            "y": 10,
            "z": 0,
            "elements": [
                "magneticraft:pneumatic_tube@0"
            ]
        },
        {
            "x": 0,
            "y": 10,
            "z": 0,
            "elements": [
                "magneticraft:pneumatic_tube@0"
            ]
        },
        {
            "x": -11,
            "y": 11,
            "z": 0,
            "elements": [
                "magneticraft:pneumatic_tube@0"
            ]
        },
        {
            "x": -10,
            "y": 11,
            "z": 0,
            "elements": [
                "magneticraft:pneumatic_tube@0"
            ]
        },
        {
            "x": -9,
            "y": 11,
            "z": 0,
            "elements": [
                "magneticraft:pneumatic_tube@0"
            ]
        },
        {
            "x": -8,
            "y": 11,
            "z": 0,
            "elements": [
                "magneticraft:pneumatic_tube@0"
            ]
        },
        {
            "x": -7,
            "y": 11,
            "z": 0,
            "elements": [
                "magneticraft:pneumatic_tube@0"
            ]
        },
        {
            "x": -6,
            "y": 11,
            "z": 0,
            "elements": [
                "magneticraft:pneumatic_tube@0"
            ]
        },
        {
            "x": -5,
            "y": 11,
            "z": 0,
            "elements": [
                "magneticraft:pneumatic_tube@0"
            ]
        },
        {
            "x": -4,
            "y": 11,
            "z": 0,
            "elements": [
                "magneticraft:pneumatic_tube@0"
            ]
        },
        {
            "x": -3,
            "y": 11,
            "z": 0,
            "elements": [
                "magneticraft:pneumatic_tube@0"
            ]
        },
        {
            "x": -2,
            "y": 11,
            "z": 0,
            "elements": [
                "magneticraft:pneumatic_tube@0"
            ]
        },
        {
            "x": -1,
            "y": 11,
            "z": 0,
            "elements": [
                "magneticraft:pneumatic_tube@0"
            ]
        },
        {
            "x": 0,
            "y": 11,
            "z": 0,
            "elements": [
                "magneticraft:pneumatic_tube@0"
            ]
        },
        {
            "x": -16,
            "y": -1,
            "z": 9,
            "elements": [
                "tconstruct:seared@0"
            ]
        },
        {
            "x": -15,
            "y": -1,
            "z": 9,
            "elements": [
                "tconstruct:seared@0"
            ]
        },
        {
            "x": -14,
            "y": -1,
            "z": 9,
            "elements": [
                "tconstruct:seared@0"
            ]
        },
        {
            "x": -13,
            "y": -1,
            "z": 9,
            "elements": [
                "tconstruct:seared@0"
            ]
        },
        {
            "x": -12,
            "y": -1,
            "z": 9,
            "elements": [
                "tconstruct:seared@0"
            ]
        },
        {
            "x": -11,
            "y": -1,
            "z": 9,
            "elements": [
                "tconstruct:seared@0"
            ]
        },
        {
            "x": -10,
            "y": -1,
            "z": 9,
            "elements": [
                "tconstruct:seared@0"
            ]
        },
        {
            "x": -9,
            "y": -1,
            "z": 9,
            "elements": [
                "tconstruct:seared@0"
            ]
        },
        {
            "x": -8,
            "y": -1,
            "z": 9,
            "elements": [
                "tconstruct:seared@0"
            ]
        },
        {
            "x": -7,
            "y": -1,
            "z": 9,
            "elements": [
                "tconstruct:seared@0"
            ]
        },
        {
            "x": -6,
            "y": -1,
            "z": 9,
            "elements": [
                "tconstruct:seared@0"
            ]
        },
        {
            "x": -5,
            "y": -1,
            "z": 9,
            "elements": [
                "tconstruct:seared@0"
            ]
        },
        {
            "x": -4,
            "y": -1,
            "z": 9,
            "elements": [
                "tconstruct:seared@0"
            ]
        },
        {
            "x": -3,
            "y": -1,
            "z": 9,
            "elements": [
                "tconstruct:seared@0"
            ]
        },
        {
            "x": -2,
            "y": -1,
            "z": 9,
            "elements": [
                "tconstruct:seared@0"
            ]
        },
        {
            "x": -1,
            "y": -1,
            "z": 9,
            "elements": [
                "tconstruct:seared@0"
            ]
        },
        {
            "x": 0,
            "y": -1,
            "z": 9,
            "elements": [
                "tconstruct:seared@0"
            ]
        },
        {
            "x": 1,
            "y": -1,
            "z": 9,
            "elements": [
                "tconstruct:seared@0"
            ]
        },
        {
            "x": 2,
            "y": -1,
            "z": 9,
            "elements": [
                "tconstruct:seared@0"
            ]
        },
        {
            "x": 0,
            "y": 9,
            "z": -5,
            "elements": [
                "immersiveengineering:metal_ladder@0"
            ]
        },
        {
            "x": 3,
            "y": -1,
            "z": 9,
            "elements": [
                "tconstruct:seared@0"
            ]
        },
        {
            "x": 4,
            "y": -1,
            "z": 9,
            "elements": [
                "tconstruct:seared@0"
            ]
        },
        {
            "x": -15,
            "y": 0,
            "z": 9,
            "elements": [
                "minecraft:concrete@0"
            ]
        },
        {
            "x": -14,
            "y": 0,
            "z": 9,
            "elements": [
                "minecraft:concrete@0"
            ]
        },
        {
            "x": -13,
            "y": 0,
            "z": 9,
            "elements": [
                "minecraft:concrete@0"
            ]
        },
        {
            "x": -12,
            "y": 0,
            "z": 9,
            "elements": [
                "minecraft:concrete@0"
            ]
        },
        {
            "x": -11,
            "y": 0,
            "z": 9,
            "elements": [
                "minecraft:concrete@0"
            ]
        },
        {
            "x": -10,
            "y": 0,
            "z": 9,
            "elements": [
                "minecraft:concrete@0"
            ]
        },
        {
            "x": -9,
            "y": 0,
            "z": 9,
            "elements": [
                "minecraft:concrete@0"
            ]
        },
        {
            "x": -8,
            "y": 0,
            "z": 9,
            "elements": [
                "minecraft:concrete@0"
            ]
        },
        {
            "x": -7,
            "y": 0,
            "z": 9,
            "elements": [
                "minecraft:concrete@0"
            ]
        },
        {
            "x": 0,
            "y": 8,
            "z": -5,
            "elements": [
                "immersiveengineering:metal_ladder@0"
            ]
        },
        {
            "x": -15,
            "y": 1,
            "z": 9,
            "elements": [
                "minecraft:concrete@0"
            ]
        },
        {
            "x": -7,
            "y": 1,
            "z": 9,
            "elements": [
                "minecraft:concrete@0"
            ]
        },
        {
            "x": -1,
            "y": 1,
            "z": 9,
            "elements": [
                "extrautils2:decorativesolid@3"
            ]
        },
        {
            "x": 0,
            "y": 1,
            "z": 9,
            "elements": [
                "extrautils2:decorativesolid@3"
            ]
        },
        {
            "x": 1,
            "y": 1,
            "z": 9,
            "elements": [
                "extrautils2:decorativesolid@3"
            ]
        },
        {
            "x": 0,
            "y": 7,
            "z": -5,
            "elements": [
                "immersiveengineering:metal_ladder@0"
            ]
        },
        {
            "x": -15,
            "y": 2,
            "z": 9,
            "elements": [
                "minecraft:concrete@0"
            ]
        },
        {
            "x": -7,
            "y": 2,
            "z": 9,
            "elements": [
                "minecraft:concrete@0"
            ]
        },
        {
            "x": -2,
            "y": 2,
            "z": 9,
            "elements": [
                "extrautils2:decorativesolid@3"
            ]
        },
        {
            "x": -1,
            "y": 2,
            "z": 9,
            "elements": [
                "extrautils2:decorativesolid@3"
            ]
        },
        {
            "x": 0,
            "y": 2,
            "z": 9,
            "elements": [
                "extrautils2:decorativesolid@3"
            ]
        },
        {
            "x": 1,
            "y": 2,
            "z": 9,
            "elements": [
                "extrautils2:decorativesolid@3"
            ]
        },
        {
            "x": 2,
            "y": 2,
            "z": 9,
            "elements": [
                "extrautils2:decorativesolid@3"
            ]
        },
        {
            "x": 0,
            "y": 6,
            "z": -5,
            "elements": [
                "immersiveengineering:metal_ladder@0"
            ]
        },
        {
            "x": -15,
            "y": 3,
            "z": 9,
            "elements": [
                "minecraft:concrete@0"
            ]
        },
        {
            "x": -7,
            "y": 3,
            "z": 9,
            "elements": [
                "minecraft:concrete@0"
            ]
        },
        {
            "x": 0,
            "y": 11,
            "z": 13,
            "elements": [
                "magneticraft:pneumatic_tube@0"
            ]
        },
        {
            "x": -3,
            "y": 3,
            "z": 9,
            "elements": [
                "extrautils2:decorativesolid@3"
            ]
        },
        {
            "x": -2,
            "y": 3,
            "z": 9,
            "elements": [
                "extrautils2:decorativesolid@3"
            ]
        },
        {
            "x": -1,
            "y": 3,
            "z": 9,
            "elements": [
                "extrautils2:decorativesolid@3"
            ]
        },
        {
            "x": 0,
            "y": 3,
            "z": 9,
            "elements": [
                "extrautils2:decorativesolid@3"
            ]
        },
        {
            "x": 1,
            "y": 3,
            "z": 9,
            "elements": [
                "extrautils2:decorativesolid@3"
            ]
        },
        {
            "x": 2,
            "y": 3,
            "z": 9,
            "elements": [
                "extrautils2:decorativesolid@3"
            ]
        },
        {
            "x": 0,
            "y": 5,
            "z": -5,
            "elements": [
                "immersiveengineering:metal_ladder@0"
            ]
        },
        {
            "x": 3,
            "y": 3,
            "z": 9,
            "elements": [
                "extrautils2:decorativesolid@3"
            ]
        },
        {
            "x": -15,
            "y": 4,
            "z": 9,
            "elements": [
                "minecraft:concrete@0"
            ]
        },
        {
            "x": -7,
            "y": 4,
            "z": 9,
            "elements": [
                "minecraft:concrete@0"
            ]
        },
        {
            "x": -4,
            "y": 4,
            "z": 9,
            "elements": [
                "extrautils2:decorativesolid@3"
            ]
        },
        {
            "x": 0,
            "y": 4,
            "z": -5,
            "elements": [
                "immersiveengineering:metal_ladder@0"
            ]
        },
        {
            "x": 4,
            "y": 4,
            "z": 9,
            "elements": [
                "extrautils2:decorativesolid@3"
            ]
        },
        {
            "x": -15,
            "y": 5,
            "z": 9,
            "elements": [
                "minecraft:concrete@15"
            ]
        },
        {
            "x": -7,
            "y": 5,
            "z": 9,
            "elements": [
                "minecraft:concrete@15"
            ]
        },
        {
            "x": -4,
            "y": 5,
            "z": 9,
            "elements": [
                "extrautils2:decorativesolid@3"
            ]
        },
        {
            "x": 0,
            "y": 3,
            "z": -5,
            "elements": [
                "immersiveengineering:metal_ladder@0"
            ]
        },
        {
            "x": 4,
            "y": 5,
            "z": 9,
            "elements": [
                "extrautils2:decorativesolid@3"
            ]
        },
        {
            "x": -4,
            "y": -1,
            "z": 22,
            "elements": [
                "tconstruct:seared@0"
            ]
        },
        {
            "x": -15,
            "y": 6,
            "z": 9,
            "elements": [
                "minecraft:concrete@0"
            ]
        },
        {
            "x": -3,
            "y": -1,
            "z": 22,
            "elements": [
                "tconstruct:seared@0"
            ]
        },
        {
            "x": -2,
            "y": -1,
            "z": 22,
            "elements": [
                "tconstruct:seared@0"
            ]
        },
        {
            "x": -1,
            "y": -1,
            "z": 22,
            "elements": [
                "tconstruct:seared@0"
            ]
        },
        {
            "x": 0,
            "y": -1,
            "z": 22,
            "elements": [
                "tconstruct:seared@0"
            ]
        },
        {
            "x": 1,
            "y": -1,
            "z": 22,
            "elements": [
                "tconstruct:seared@0"
            ]
        },
        {
            "x": 2,
            "y": -1,
            "z": 22,
            "elements": [
                "tconstruct:seared@0"
            ]
        },
        {
            "x": 3,
            "y": -1,
            "z": 22,
            "elements": [
                "tconstruct:seared@0"
            ]
        },
        {
            "x": 4,
            "y": -1,
            "z": 22,
            "elements": [
                "tconstruct:seared@0"
            ]
        },
        {
            "x": -7,
            "y": 6,
            "z": 9,
            "elements": [
                "minecraft:concrete@0"
            ]
        },
        {
            "x": -4,
            "y": 6,
            "z": 9,
            "elements": [
                "extrautils2:decorativesolid@3"
            ]
        },
        {
            "x": 0,
            "y": 2,
            "z": -5,
            "elements": [
                "immersiveengineering:metal_ladder@0"
            ]
        },
        {
            "x": 4,
            "y": 6,
            "z": 9,
            "elements": [
                "extrautils2:decorativesolid@3"
            ]
        },
        {
            "x": -4,
            "y": 0,
            "z": 22,
            "elements": [
                "skyresources:petrifiedplanks@0"
            ]
        },
        {
            "x": -15,
            "y": 7,
            "z": 9,
            "elements": [
                "minecraft:concrete@0"
            ]
        },
        {
            "x": -3,
            "y": 0,
            "z": 22,
            "elements": [
                "skyresources:petrifiedplanks@0"
            ]
        },
        {
            "x": -2,
            "y": 0,
            "z": 22,
            "elements": [
                "skyresources:petrifiedplanks@0"
            ]
        },
        {
            "x": -1,
            "y": 0,
            "z": 22,
            "elements": [
                "skyresources:petrifiedplanks@0"
            ]
        },
        {
            "x": 0,
            "y": 0,
            "z": 22,
            "elements": [
                "skyresources:petrifiedplanks@0"
            ]
        },
        {
            "x": -16,
            "y": -1,
            "z": 5,
            "elements": [
                "tconstruct:seared@0"
            ]
        },
        {
            "x": 1,
            "y": 0,
            "z": 22,
            "elements": [
                "skyresources:petrifiedplanks@0"
            ]
        },
        {
            "x": -15,
            "y": -1,
            "z": 5,
            "elements": [
                "tconstruct:seared@0"
            ]
        },
        {
            "x": -14,
            "y": -1,
            "z": 5,
            "elements": [
                "tconstruct:seared@0"
            ]
        },
        {
            "x": 2,
            "y": 0,
            "z": 22,
            "elements": [
                "skyresources:petrifiedplanks@0"
            ]
        },
        {
            "x": -13,
            "y": -1,
            "z": 5,
            "elements": [
                "tconstruct:seared@0"
            ]
        },
        {
            "x": 3,
            "y": 0,
            "z": 22,
            "elements": [
                "skyresources:petrifiedplanks@0"
            ]
        },
        {
            "x": -12,
            "y": -1,
            "z": 5,
            "elements": [
                "tconstruct:seared@0"
            ]
        },
        {
            "x": 4,
            "y": 0,
            "z": 22,
            "elements": [
                "skyresources:petrifiedplanks@0"
            ]
        },
        {
            "x": -11,
            "y": -1,
            "z": 5,
            "elements": [
                "tconstruct:seared@0"
            ]
        },
        {
            "x": -7,
            "y": 7,
            "z": 9,
            "elements": [
                "minecraft:concrete@0"
            ]
        },
        {
            "x": -10,
            "y": -1,
            "z": 5,
            "elements": [
                "tconstruct:seared@0"
            ]
        },
        {
            "x": -9,
            "y": -1,
            "z": 5,
            "elements": [
                "tconstruct:seared@0"
            ]
        },
        {
            "x": -8,
            "y": -1,
            "z": 5,
            "elements": [
                "tconstruct:seared@0"
            ]
        },
        {
            "x": -4,
            "y": 7,
            "z": 9,
            "elements": [
                "extrautils2:decorativesolid@3"
            ]
        },
        {
            "x": -7,
            "y": -1,
            "z": 5,
            "elements": [
                "tconstruct:seared@0"
            ]
        },
        {
            "x": -6,
            "y": -1,
            "z": 5,
            "elements": [
                "tconstruct:seared@0"
            ]
        },
        {
            "x": -5,
            "y": -1,
            "z": 5,
            "elements": [
                "tconstruct:seared@0"
            ]
        },
        {
            "x": -4,
            "y": -1,
            "z": 5,
            "elements": [
                "tconstruct:seared@0"
            ]
        },
        {
            "x": -3,
            "y": -1,
            "z": 5,
            "elements": [
                "tconstruct:seared@0"
            ]
        },
        {
            "x": -2,
            "y": -1,
            "z": 5,
            "elements": [
                "tconstruct:seared@0"
            ]
        },
        {
            "x": 4,
            "y": 9,
            "z": -1,
            "elements": [
                "extrautils2:decorativesolid@3"
            ]
        },
        {
            "x": 0,
            "y": 1,
            "z": -5,
            "elements": [
                "immersiveengineering:metal_ladder@0"
            ]
        },
        {
            "x": -1,
            "y": -1,
            "z": 5,
            "elements": [
                "tconstruct:seared@0"
            ]
        },
        {
            "x": 0,
            "y": -1,
            "z": 5,
            "elements": [
                "tconstruct:seared@0"
            ]
        },
        {
            "x": 3,
            "y": 9,
            "z": -1,
            "elements": [
                "extrautils2:decorativesolid@3"
            ]
        },
        {
            "x": 4,
            "y": 7,
            "z": 9,
            "elements": [
                "extrautils2:decorativesolid@3"
            ]
        },
        {
            "x": 1,
            "y": -1,
            "z": 5,
            "elements": [
                "tconstruct:seared@0"
            ]
        },
        {
            "x": 2,
            "y": 9,
            "z": -1,
            "elements": [
                "extrautils2:decorativesolid@3"
            ]
        },
        {
            "x": 1,
            "y": 9,
            "z": -1,
            "elements": [
                "extrautils2:decorativesolid@3"
            ]
        },
        {
            "x": 2,
            "y": -1,
            "z": 5,
            "elements": [
                "tconstruct:seared@0"
            ]
        },
        {
            "x": 0,
            "y": 9,
            "z": -1,
            "elements": [
                "extrautils2:decorativesolid@3"
            ]
        },
        {
            "x": 3,
            "y": -1,
            "z": 5,
            "elements": [
                "tconstruct:seared@0"
            ]
        },
        {
            "x": -1,
            "y": 9,
            "z": -1,
            "elements": [
                "extrautils2:decorativesolid@3"
            ]
        },
        {
            "x": 4,
            "y": -1,
            "z": 5,
            "elements": [
                "tconstruct:seared@0"
            ]
        },
        {
            "x": -2,
            "y": 9,
            "z": -1,
            "elements": [
                "extrautils2:decorativesolid@3"
            ]
        },
        {
            "x": -3,
            "y": 9,
            "z": -1,
            "elements": [
                "extrautils2:decorativesolid@3"
            ]
        },
        {
            "x": -4,
            "y": 9,
            "z": -1,
            "elements": [
                "extrautils2:decorativesolid@3"
            ]
        },
        {
            "x": -7,
            "y": 9,
            "z": -1,
            "elements": [
                "minecraft:concrete@0"
            ]
        },
        {
            "x": -8,
            "y": 9,
            "z": -1,
            "elements": [
                "minecraft:concrete@0"
            ]
        },
        {
            "x": -4,
            "y": 1,
            "z": 22,
            "elements": [
                "skyresources:petrifiedplanks@0"
            ]
        },
        {
            "x": -9,
            "y": 9,
            "z": -1,
            "elements": [
                "minecraft:concrete@0"
            ]
        },
        {
            "x": -15,
            "y": 8,
            "z": 9,
            "elements": [
                "minecraft:concrete@0"
            ]
        },
        {
            "x": -3,
            "y": 1,
            "z": 22,
            "elements": [
                "skyresources:petrifiedplanks@0"
            ]
        },
        {
            "x": -10,
            "y": 9,
            "z": -1,
            "elements": [
                "minecraft:concrete@0"
            ]
        },
        {
            "x": -2,
            "y": 1,
            "z": 22,
            "elements": [
                "skyresources:petrifiedplanks@0"
            ]
        },
        {
            "x": -1,
            "y": 1,
            "z": 22,
            "elements": [
                "skyresources:petrifiedplanks@0"
            ]
        },
        {
            "x": -11,
            "y": 9,
            "z": -1,
            "elements": [
                "minecraft:concrete@0"
            ]
        },
        {
            "x": 0,
            "y": 1,
            "z": 22,
            "elements": [
                "skyresources:petrifiedplanks@0"
            ]
        },
        {
            "x": -12,
            "y": 9,
            "z": -1,
            "elements": [
                "minecraft:concrete@0"
            ]
        },
        {
            "x": 1,
            "y": 1,
            "z": 22,
            "elements": [
                "skyresources:petrifiedplanks@0"
            ]
        },
        {
            "x": -13,
            "y": 9,
            "z": -1,
            "elements": [
                "minecraft:concrete@0"
            ]
        },
        {
            "x": -14,
            "y": 9,
            "z": -1,
            "elements": [
                "minecraft:concrete@0"
            ]
        },
        {
            "x": 2,
            "y": 1,
            "z": 22,
            "elements": [
                "skyresources:petrifiedplanks@0"
            ]
        },
        {
            "x": -15,
            "y": 9,
            "z": -1,
            "elements": [
                "minecraft:concrete@0"
            ]
        },
        {
            "x": 3,
            "y": 1,
            "z": 22,
            "elements": [
                "skyresources:petrifiedplanks@0"
            ]
        },
        {
            "x": 4,
            "y": 1,
            "z": 22,
            "elements": [
                "skyresources:petrifiedplanks@0"
            ]
        },
        {
            "x": -7,
            "y": 8,
            "z": 9,
            "elements": [
                "minecraft:concrete@0"
            ]
        },
        {
            "x": -4,
            "y": 8,
            "z": 9,
            "elements": [
                "extrautils2:decorativesolid@3"
            ]
        },
        {
            "x": 0,
            "y": 0,
            "z": -5,
            "elements": [
                "immersiveengineering:metal_ladder@0"
            ]
        },
        {
            "x": 4,
            "y": 8,
            "z": -1,
            "elements": [
                "extrautils2:decorativesolid@3"
            ]
        },
        {
            "x": 4,
            "y": 8,
            "z": 9,
            "elements": [
                "extrautils2:decorativesolid@3"
            ]
        },
        {
            "x": -4,
            "y": 8,
            "z": -1,
            "elements": [
                "extrautils2:decorativesolid@3"
            ]
        },
        {
            "x": -7,
            "y": 8,
            "z": -1,
            "elements": [
                "minecraft:concrete@0"
            ]
        },
        {
            "x": -4,
            "y": 2,
            "z": 22,
            "elements": [
                "skyresources:petrifiedplanks@0"
            ]
        },
        {
            "x": -15,
            "y": 9,
            "z": 9,
            "elements": [
                "minecraft:concrete@0"
            ]
        },
        {
            "x": -3,
            "y": 2,
            "z": 22,
            "elements": [
                "skyresources:petrifiedplanks@0"
            ]
        },
        {
            "x": -14,
            "y": 9,
            "z": 9,
            "elements": [
                "minecraft:concrete@0"
            ]
        },
        {
            "x": -2,
            "y": 2,
            "z": 22,
            "elements": [
                "skyresources:petrifiedplanks@0"
            ]
        },
        {
            "x": -1,
            "y": 2,
            "z": 22,
            "elements": [
                "skyresources:petrifiedplanks@0"
            ]
        },
        {
            "x": -13,
            "y": 9,
            "z": 9,
            "elements": [
                "minecraft:concrete@0"
            ]
        },
        {
            "x": 0,
            "y": 2,
            "z": 22,
            "elements": [
                "skyresources:petrifiedplanks@0"
            ]
        },
        {
            "x": -12,
            "y": 9,
            "z": 9,
            "elements": [
                "minecraft:concrete@0"
            ]
        },
        {
            "x": 1,
            "y": 2,
            "z": 22,
            "elements": [
                "skyresources:petrifiedplanks@0"
            ]
        },
        {
            "x": -11,
            "y": 9,
            "z": 9,
            "elements": [
                "minecraft:concrete@0"
            ]
        },
        {
            "x": -10,
            "y": 9,
            "z": 9,
            "elements": [
                "minecraft:concrete@0"
            ]
        },
        {
            "x": 2,
            "y": 2,
            "z": 22,
            "elements": [
                "skyresources:petrifiedplanks@0"
            ]
        },
        {
            "x": -9,
            "y": 9,
            "z": 9,
            "elements": [
                "minecraft:concrete@0"
            ]
        },
        {
            "x": -15,
            "y": 8,
            "z": -1,
            "elements": [
                "minecraft:concrete@0"
            ]
        },
        {
            "x": 3,
            "y": 2,
            "z": 22,
            "elements": [
                "skyresources:petrifiedplanks@0"
            ]
        },
        {
            "x": -8,
            "y": 9,
            "z": 9,
            "elements": [
                "minecraft:concrete@0"
            ]
        },
        {
            "x": 4,
            "y": 2,
            "z": 22,
            "elements": [
                "skyresources:petrifiedplanks@0"
            ]
        },
        {
            "x": -7,
            "y": 9,
            "z": 9,
            "elements": [
                "minecraft:concrete@0"
            ]
        },
        {
            "x": -4,
            "y": 9,
            "z": 9,
            "elements": [
                "extrautils2:decorativesolid@3"
            ]
        },
        {
            "x": -3,
            "y": 9,
            "z": 9,
            "elements": [
                "extrautils2:decorativesolid@3"
            ]
        },
        {
            "x": -2,
            "y": 9,
            "z": 9,
            "elements": [
                "extrautils2:decorativesolid@3"
            ]
        },
        {
            "x": -1,
            "y": 9,
            "z": 9,
            "elements": [
                "extrautils2:decorativesolid@3"
            ]
        },
        {
            "x": 4,
            "y": -1,
            "z": -5,
            "elements": [
                "tconstruct:seared@0"
            ]
        },
        {
            "x": 0,
            "y": 9,
            "z": 9,
            "elements": [
                "extrautils2:decorativesolid@3"
            ]
        },
        {
            "x": 3,
            "y": -1,
            "z": -5,
            "elements": [
                "tconstruct:seared@0"
            ]
        },
        {
            "x": 1,
            "y": 9,
            "z": 9,
            "elements": [
                "extrautils2:decorativesolid@3"
            ]
        },
        {
            "x": 2,
            "y": -1,
            "z": -5,
            "elements": [
                "tconstruct:seared@0"
            ]
        },
        {
            "x": 1,
            "y": -1,
            "z": -5,
            "elements": [
                "tconstruct:seared@0"
            ]
        },
        {
            "x": 2,
            "y": 9,
            "z": 9,
            "elements": [
                "extrautils2:decorativesolid@3"
            ]
        },
        {
            "x": 0,
            "y": -1,
            "z": -5,
            "elements": [
                "tconstruct:seared@0"
            ]
        },
        {
            "x": 3,
            "y": 9,
            "z": 9,
            "elements": [
                "extrautils2:decorativesolid@3"
            ]
        },
        {
            "x": 4,
            "y": 7,
            "z": -1,
            "elements": [
                "extrautils2:decorativesolid@3"
            ]
        },
        {
            "x": 4,
            "y": 9,
            "z": 9,
            "elements": [
                "extrautils2:decorativesolid@3"
            ]
        },
        {
            "x": -1,
            "y": -1,
            "z": -5,
            "elements": [
                "tconstruct:seared@0"
            ]
        },
        {
            "x": -2,
            "y": -1,
            "z": -5,
            "elements": [
                "tconstruct:seared@0"
            ]
        },
        {
            "x": -3,
            "y": -1,
            "z": -5,
            "elements": [
                "tconstruct:seared@0"
            ]
        },
        {
            "x": -4,
            "y": -1,
            "z": -5,
            "elements": [
                "tconstruct:seared@0"
            ]
        },
        {
            "x": -5,
            "y": -1,
            "z": -5,
            "elements": [
                "tconstruct:seared@0"
            ]
        },
        {
            "x": -6,
            "y": -1,
            "z": -5,
            "elements": [
                "tconstruct:seared@0"
            ]
        },
        {
            "x": -7,
            "y": -1,
            "z": -5,
            "elements": [
                "tconstruct:seared@0"
            ]
        },
        {
            "x": -8,
            "y": -1,
            "z": -5,
            "elements": [
                "tconstruct:seared@0"
            ]
        },
        {
            "x": -4,
            "y": 7,
            "z": -1,
            "elements": [
                "extrautils2:decorativesolid@3"
            ]
        },
        {
            "x": -9,
            "y": -1,
            "z": -5,
            "elements": [
                "tconstruct:seared@0"
            ]
        },
        {
            "x": -10,
            "y": -1,
            "z": -5,
            "elements": [
                "tconstruct:seared@0"
            ]
        },
        {
            "x": -11,
            "y": -1,
            "z": -5,
            "elements": [
                "tconstruct:seared@0"
            ]
        },
        {
            "x": -7,
            "y": 7,
            "z": -1,
            "elements": [
                "minecraft:concrete@0"
            ]
        },
        {
            "x": -12,
            "y": -1,
            "z": -5,
            "elements": [
                "tconstruct:seared@0"
            ]
        },
        {
            "x": -4,
            "y": 3,
            "z": 22,
            "elements": [
                "skyresources:petrifiedplanks@0"
            ]
        },
        {
            "x": -13,
            "y": -1,
            "z": -5,
            "elements": [
                "tconstruct:seared@0"
            ]
        },
        {
            "x": -3,
            "y": 3,
            "z": 22,
            "elements": [
                "skyresources:petrifiedplanks@0"
            ]
        },
        {
            "x": -14,
            "y": -1,
            "z": -5,
            "elements": [
                "tconstruct:seared@0"
            ]
        },
        {
            "x": -2,
            "y": 3,
            "z": 22,
            "elements": [
                "skyresources:petrifiedplanks@0"
            ]
        },
        {
            "x": -1,
            "y": 3,
            "z": 22,
            "elements": [
                "skyresources:petrifiedplanks@0"
            ]
        },
        {
            "x": -15,
            "y": -1,
            "z": -5,
            "elements": [
                "tconstruct:seared@0"
            ]
        },
        {
            "x": 0,
            "y": 3,
            "z": 22,
            "elements": [
                "skyresources:petrifiedplanks@0"
            ]
        },
        {
            "x": -16,
            "y": -1,
            "z": -5,
            "elements": [
                "tconstruct:seared@0"
            ]
        },
        {
            "x": 1,
            "y": 3,
            "z": 22,
            "elements": [
                "skyresources:petrifiedplanks@0"
            ]
        },
        {
            "x": -15,
            "y": 2,
            "z": 5,
            "elements": [
                "minecraft:concrete@0"
            ]
        },
        {
            "x": -14,
            "y": 2,
            "z": 5,
            "elements": [
                "minecraft:concrete@0"
            ]
        },
        {
            "x": 2,
            "y": 3,
            "z": 22,
            "elements": [
                "skyresources:petrifiedplanks@0"
            ]
        },
        {
            "x": -13,
            "y": 2,
            "z": 5,
            "elements": [
                "minecraft:concrete@0"
            ]
        },
        {
            "x": -15,
            "y": 7,
            "z": -1,
            "elements": [
                "minecraft:concrete@0"
            ]
        },
        {
            "x": 3,
            "y": 3,
            "z": 22,
            "elements": [
                "skyresources:petrifiedplanks@0"
            ]
        },
        {
            "x": -12,
            "y": 2,
            "z": 5,
            "elements": [
                "minecraft:concrete@0"
            ]
        },
        {
            "x": 4,
            "y": 3,
            "z": 22,
            "elements": [
                "skyresources:petrifiedplanks@0"
            ]
        },
        {
            "x": -11,
            "y": 2,
            "z": 5,
            "elements": [
                "minecraft:concrete@0"
            ]
        },
        {
            "x": -10,
            "y": 2,
            "z": 5,
            "elements": [
                "minecraft:concrete@0"
            ]
        },
        {
            "x": -9,
            "y": 2,
            "z": 5,
            "elements": [
                "minecraft:concrete@0"
            ]
        },
        {
            "x": -8,
            "y": 2,
            "z": 5,
            "elements": [
                "minecraft:concrete@0"
            ]
        },
        {
            "x": -7,
            "y": 2,
            "z": 5,
            "elements": [
                "minecraft:concrete@0"
            ]
        },
        {
            "x": 4,
            "y": 6,
            "z": -1,
            "elements": [
                "extrautils2:decorativesolid@3"
            ]
        },
        {
            "x": -4,
            "y": 6,
            "z": -1,
            "elements": [
                "extrautils2:decorativesolid@3"
            ]
        },
        {
            "x": -7,
            "y": 6,
            "z": -1,
            "elements": [
                "minecraft:concrete@0"
            ]
        },
        {
            "x": -4,
            "y": 4,
            "z": 22,
            "elements": [
                "skyresources:petrifiedplanks@0"
            ]
        },
        {
            "x": -3,
            "y": 4,
            "z": 22,
            "elements": [
                "skyresources:petrifiedplanks@0"
            ]
        },
        {
            "x": -2,
            "y": 4,
            "z": 22,
            "elements": [
                "skyresources:petrifiedplanks@0"
            ]
        },
        {
            "x": -1,
            "y": 4,
            "z": 22,
            "elements": [
                "skyresources:petrifiedplanks@0"
            ]
        },
        {
            "x": 0,
            "y": 4,
            "z": 22,
            "elements": [
                "skyresources:petrifiedplanks@0"
            ]
        },
        {
            "x": 1,
            "y": 4,
            "z": 22,
            "elements": [
                "skyresources:petrifiedplanks@0"
            ]
        },
        {
            "x": -15,
            "y": 3,
            "z": 5,
            "elements": [
                "minecraft:concrete@0"
            ]
        },
        {
            "x": 2,
            "y": 4,
            "z": 22,
            "elements": [
                "skyresources:petrifiedplanks@0"
            ]
        },
        {
            "x": -15,
            "y": 6,
            "z": -1,
            "elements": [
                "minecraft:concrete@0"
            ]
        },
        {
            "x": 3,
            "y": 4,
            "z": 22,
            "elements": [
                "skyresources:petrifiedplanks@0"
            ]
        },
        {
            "x": 4,
            "y": 4,
            "z": 22,
            "elements": [
                "skyresources:petrifiedplanks@0"
            ]
        },
        {
            "x": -7,
            "y": 3,
            "z": 5,
            "elements": [
                "minecraft:concrete@0"
            ]
        },
        {
            "x": 0,
            "y": 11,
            "z": 9,
            "elements": [
                "magneticraft:pneumatic_tube@0"
            ]
        },
        {
            "x": -3,
            "y": 3,
            "z": 5,
            "elements": [
                "extrautils2:decorativesolid@3"
            ]
        },
        {
            "x": -2,
            "y": 3,
            "z": 5,
            "elements": [
                "extrautils2:decorativesolid@3"
            ]
        },
        {
            "x": -1,
            "y": 3,
            "z": 5,
            "elements": [
                "extrautils2:decorativesolid@3"
            ]
        },
        {
            "x": 4,
            "y": 5,
            "z": -1,
            "elements": [
                "extrautils2:decorativesolid@3"
            ]
        },
        {
            "x": 0,
            "y": 3,
            "z": 5,
            "elements": [
                "extrautils2:decorativesolid@3"
            ]
        },
        {
            "x": 1,
            "y": 3,
            "z": 5,
            "elements": [
                "extrautils2:decorativesolid@3"
            ]
        },
        {
            "x": 2,
            "y": 3,
            "z": 5,
            "elements": [
                "extrautils2:decorativesolid@3"
            ]
        },
        {
            "x": 3,
            "y": 3,
            "z": 5,
            "elements": [
                "extrautils2:decorativesolid@3"
            ]
        },
        {
            "x": -4,
            "y": 5,
            "z": -1,
            "elements": [
                "extrautils2:decorativesolid@3"
            ]
        },
        {
            "x": -7,
            "y": 5,
            "z": -1,
            "elements": [
                "minecraft:concrete@15"
            ]
        },
        {
            "x": -4,
            "y": 5,
            "z": 22,
            "elements": [
                "skyresources:petrifiedplanks@0"
            ]
        },
        {
            "x": -3,
            "y": 5,
            "z": 22,
            "elements": [
                "skyresources:petrifiedplanks@0"
            ]
        },
        {
            "x": -2,
            "y": 5,
            "z": 22,
            "elements": [
                "skyresources:petrifiedplanks@0"
            ]
        },
        {
            "x": -1,
            "y": 5,
            "z": 22,
            "elements": [
                "skyresources:petrifiedplanks@0"
            ]
        },
        {
            "x": 0,
            "y": 5,
            "z": 22,
            "elements": [
                "skyresources:petrifiedplanks@0"
            ]
        },
        {
            "x": 1,
            "y": 5,
            "z": 22,
            "elements": [
                "skyresources:petrifiedplanks@0"
            ]
        },
        {
            "x": -15,
            "y": 4,
            "z": 5,
            "elements": [
                "minecraft:concrete@0"
            ]
        },
        {
            "x": 2,
            "y": 5,
            "z": 22,
            "elements": [
                "skyresources:petrifiedplanks@0"
            ]
        },
        {
            "x": -15,
            "y": 5,
            "z": -1,
            "elements": [
                "minecraft:concrete@15"
            ]
        },
        {
            "x": 3,
            "y": 5,
            "z": 22,
            "elements": [
                "skyresources:petrifiedplanks@0"
            ]
        },
        {
            "x": 4,
            "y": 5,
            "z": 22,
            "elements": [
                "skyresources:petrifiedplanks@0"
            ]
        },
        {
            "x": -7,
            "y": 4,
            "z": 5,
            "elements": [
                "minecraft:concrete@0"
            ]
        },
        {
            "x": -4,
            "y": 4,
            "z": 5,
            "elements": [
                "extrautils2:decorativesolid@3"
            ]
        },
        {
            "x": 4,
            "y": 4,
            "z": -1,
            "elements": [
                "extrautils2:decorativesolid@3"
            ]
        },
        {
            "x": 4,
            "y": 4,
            "z": 5,
            "elements": [
                "extrautils2:decorativesolid@3"
            ]
        },
        {
            "x": -4,
            "y": 4,
            "z": -1,
            "elements": [
                "extrautils2:decorativesolid@3"
            ]
        },
        {
            "x": -7,
            "y": 4,
            "z": -1,
            "elements": [
                "minecraft:concrete@0"
            ]
        },
        {
            "x": -4,
            "y": 6,
            "z": 22,
            "elements": [
                "skyresources:petrifiedplanks@0"
            ]
        },
        {
            "x": -3,
            "y": 6,
            "z": 22,
            "elements": [
                "skyresources:petrifiedplanks@0"
            ]
        },
        {
            "x": -2,
            "y": 6,
            "z": 22,
            "elements": [
                "skyresources:petrifiedplanks@0"
            ]
        },
        {
            "x": -1,
            "y": 6,
            "z": 22,
            "elements": [
                "skyresources:petrifiedplanks@0"
            ]
        },
        {
            "x": 0,
            "y": 6,
            "z": 22,
            "elements": [
                "skyresources:petrifiedplanks@0"
            ]
        },
        {
            "x": 1,
            "y": 6,
            "z": 22,
            "elements": [
                "skyresources:petrifiedplanks@0"
            ]
        },
        {
            "x": -15,
            "y": 5,
            "z": 5,
            "elements": [
                "minecraft:concrete@0"
            ]
        },
        {
            "x": 2,
            "y": 6,
            "z": 22,
            "elements": [
                "skyresources:petrifiedplanks@0"
            ]
        },
        {
            "x": -15,
            "y": 4,
            "z": -1,
            "elements": [
                "minecraft:concrete@0"
            ]
        },
        {
            "x": 3,
            "y": 6,
            "z": 22,
            "elements": [
                "skyresources:petrifiedplanks@0"
            ]
        },
        {
            "x": 4,
            "y": 6,
            "z": 22,
            "elements": [
                "skyresources:petrifiedplanks@0"
            ]
        },
        {
            "x": -7,
            "y": 5,
            "z": 5,
            "elements": [
                "minecraft:concrete@0"
            ]
        },
        {
            "x": -4,
            "y": 5,
            "z": 5,
            "elements": [
                "extrautils2:decorativesolid@3"
            ]
        },
        {
            "x": 3,
            "y": 3,
            "z": -1,
            "elements": [
                "extrautils2:decorativesolid@3"
            ]
        },
        {
            "x": 2,
            "y": 3,
            "z": -1,
            "elements": [
                "extrautils2:decorativesolid@3"
            ]
        },
        {
            "x": 1,
            "y": 3,
            "z": -1,
            "elements": [
                "extrautils2:decorativesolid@3"
            ]
        },
        {
            "x": 0,
            "y": 3,
            "z": -1,
            "elements": [
                "extrautils2:decorativesolid@3"
            ]
        },
        {
            "x": -1,
            "y": 3,
            "z": -1,
            "elements": [
                "extrautils2:decorativesolid@3"
            ]
        },
        {
            "x": 4,
            "y": 5,
            "z": 5,
            "elements": [
                "extrautils2:decorativesolid@3"
            ]
        },
        {
            "x": -2,
            "y": 3,
            "z": -1,
            "elements": [
                "extrautils2:decorativesolid@3"
            ]
        },
        {
            "x": -3,
            "y": 3,
            "z": -1,
            "elements": [
                "extrautils2:decorativesolid@3"
            ]
        },
        {
            "x": -7,
            "y": 3,
            "z": -1,
            "elements": [
                "minecraft:concrete@0"
            ]
        },
        {
            "x": -4,
            "y": 7,
            "z": 22,
            "elements": [
                "skyresources:petrifiedplanks@0"
            ]
        },
        {
            "x": -3,
            "y": 7,
            "z": 22,
            "elements": [
                "skyresources:petrifiedplanks@0"
            ]
        },
        {
            "x": -2,
            "y": 7,
            "z": 22,
            "elements": [
                "skyresources:petrifiedplanks@0"
            ]
        },
        {
            "x": -1,
            "y": 7,
            "z": 22,
            "elements": [
                "skyresources:petrifiedplanks@0"
            ]
        },
        {
            "x": 0,
            "y": 7,
            "z": 22,
            "elements": [
                "skyresources:petrifiedplanks@0"
            ]
        },
        {
            "x": -4,
            "y": -1,
            "z": 18,
            "elements": [
                "tconstruct:seared@0"
            ]
        },
        {
            "x": 1,
            "y": 7,
            "z": 22,
            "elements": [
                "skyresources:petrifiedplanks@0"
            ]
        },
        {
            "x": -15,
            "y": 6,
            "z": 5,
            "elements": [
                "minecraft:concrete@0"
            ]
        },
        {
            "x": -3,
            "y": -1,
            "z": 18,
            "elements": [
                "tconstruct:seared@0"
            ]
        },
        {
            "x": -2,
            "y": -1,
            "z": 18,
            "elements": [
                "tconstruct:seared@0"
            ]
        },
        {
            "x": 2,
            "y": 7,
            "z": 22,
            "elements": [
                "skyresources:petrifiedplanks@0"
            ]
        },
        {
            "x": -1,
            "y": -1,
            "z": 18,
            "elements": [
                "tconstruct:seared@0"
            ]
        },
        {
            "x": -15,
            "y": 3,
            "z": -1,
            "elements": [
                "minecraft:concrete@0"
            ]
        },
        {
            "x": 3,
            "y": 7,
            "z": 22,
            "elements": [
                "skyresources:petrifiedplanks@0"
            ]
        },
        {
            "x": 0,
            "y": -1,
            "z": 18,
            "elements": [
                "tconstruct:seared@0"
            ]
        },
        {
            "x": 4,
            "y": 7,
            "z": 22,
            "elements": [
                "skyresources:petrifiedplanks@0"
            ]
        },
        {
            "x": 1,
            "y": -1,
            "z": 18,
            "elements": [
                "tconstruct:seared@0"
            ]
        },
        {
            "x": 2,
            "y": -1,
            "z": 18,
            "elements": [
                "tconstruct:seared@0"
            ]
        },
        {
            "x": 3,
            "y": -1,
            "z": 18,
            "elements": [
                "tconstruct:seared@0"
            ]
        },
        {
            "x": 4,
            "y": -1,
            "z": 18,
            "elements": [
                "tconstruct:seared@0"
            ]
        },
        {
            "x": -7,
            "y": 6,
            "z": 5,
            "elements": [
                "minecraft:concrete@0"
            ]
        },
        {
            "x": -4,
            "y": 6,
            "z": 5,
            "elements": [
                "extrautils2:decorativesolid@3"
            ]
        },
        {
            "x": 2,
            "y": 2,
            "z": -1,
            "elements": [
                "extrautils2:decorativesolid@3"
            ]
        },
        {
            "x": 1,
            "y": 2,
            "z": -1,
            "elements": [
                "extrautils2:decorativesolid@3"
            ]
        },
        {
            "x": 0,
            "y": 2,
            "z": -1,
            "elements": [
                "extrautils2:decorativesolid@3"
            ]
        },
        {
            "x": -1,
            "y": 2,
            "z": -1,
            "elements": [
                "extrautils2:decorativesolid@3"
            ]
        },
        {
            "x": 4,
            "y": 6,
            "z": 5,
            "elements": [
                "extrautils2:decorativesolid@3"
            ]
        },
        {
            "x": -2,
            "y": 2,
            "z": -1,
            "elements": [
                "extrautils2:decorativesolid@3"
            ]
        },
        {
            "x": -7,
            "y": 2,
            "z": -1,
            "elements": [
                "minecraft:concrete@0"
            ]
        },
        {
            "x": -4,
            "y": 8,
            "z": 22,
            "elements": [
                "skyresources:petrifiedplanks@0"
            ]
        },
        {
            "x": -3,
            "y": 8,
            "z": 22,
            "elements": [
                "skyresources:petrifiedplanks@0"
            ]
        },
        {
            "x": -2,
            "y": 8,
            "z": 22,
            "elements": [
                "skyresources:petrifiedplanks@0"
            ]
        },
        {
            "x": -1,
            "y": 8,
            "z": 22,
            "elements": [
                "skyresources:petrifiedplanks@0"
            ]
        },
        {
            "x": 0,
            "y": 8,
            "z": 22,
            "elements": [
                "skyresources:petrifiedplanks@0"
            ]
        },
        {
            "x": -4,
            "y": 0,
            "z": 18,
            "elements": [
                "skyresources:petrifiedplanks@0"
            ]
        },
        {
            "x": 1,
            "y": 8,
            "z": 22,
            "elements": [
                "skyresources:petrifiedplanks@0"
            ]
        },
        {
            "x": -15,
            "y": 7,
            "z": 5,
            "elements": [
                "minecraft:concrete@0"
            ]
        },
        {
            "x": -14,
            "y": 7,
            "z": 5,
            "elements": [
                "minecraft:concrete@0"
            ]
        },
        {
            "x": 2,
            "y": 8,
            "z": 22,
            "elements": [
                "skyresources:petrifiedplanks@0"
            ]
        },
        {
            "x": -15,
            "y": 2,
            "z": -1,
            "elements": [
                "minecraft:concrete@0"
            ]
        },
        {
            "x": 3,
            "y": 8,
            "z": 22,
            "elements": [
                "skyresources:petrifiedplanks@0"
            ]
        },
        {
            "x": -13,
            "y": 7,
            "z": 5,
            "elements": [
                "minecraft:concrete@0"
            ]
        },
        {
            "x": -16,
            "y": -1,
            "z": 1,
            "elements": [
                "tconstruct:seared@0"
            ]
        },
        {
            "x": -12,
            "y": 7,
            "z": 5,
            "elements": [
                "minecraft:concrete@0"
            ]
        },
        {
            "x": 4,
            "y": 8,
            "z": 22,
            "elements": [
                "skyresources:petrifiedplanks@0"
            ]
        },
        {
            "x": -15,
            "y": -1,
            "z": 1,
            "elements": [
                "tconstruct:seared@0"
            ]
        },
        {
            "x": -11,
            "y": 7,
            "z": 5,
            "elements": [
                "minecraft:concrete@0"
            ]
        },
        {
            "x": -14,
            "y": -1,
            "z": 1,
            "elements": [
                "tconstruct:seared@0"
            ]
        },
        {
            "x": -10,
            "y": 7,
            "z": 5,
            "elements": [
                "minecraft:concrete@0"
            ]
        },
        {
            "x": -13,
            "y": -1,
            "z": 1,
            "elements": [
                "tconstruct:seared@0"
            ]
        },
        {
            "x": -9,
            "y": 7,
            "z": 5,
            "elements": [
                "minecraft:concrete@0"
            ]
        },
        {
            "x": -12,
            "y": -1,
            "z": 1,
            "elements": [
                "tconstruct:seared@0"
            ]
        },
        {
            "x": -8,
            "y": 7,
            "z": 5,
            "elements": [
                "minecraft:concrete@0"
            ]
        },
        {
            "x": 4,
            "y": 0,
            "z": 18,
            "elements": [
                "modularmachinery:blockoutputbus@1"
            ]
        },
        {
            "x": -11,
            "y": -1,
            "z": 1,
            "elements": [
                "tconstruct:seared@0"
            ]
        },
        {
            "x": -7,
            "y": 7,
            "z": 5,
            "elements": [
                "minecraft:concrete@0"
            ]
        },
        {
            "x": -10,
            "y": -1,
            "z": 1,
            "elements": [
                "tconstruct:seared@0"
            ]
        },
        {
            "x": -9,
            "y": -1,
            "z": 1,
            "elements": [
                "tconstruct:seared@0"
            ]
        },
        {
            "x": -8,
            "y": -1,
            "z": 1,
            "elements": [
                "tconstruct:seared@0"
            ]
        },
        {
            "x": -4,
            "y": 7,
            "z": 5,
            "elements": [
                "extrautils2:decorativesolid@3"
            ]
        },
        {
            "x": -7,
            "y": -1,
            "z": 1,
            "elements": [
                "tconstruct:seared@0"
            ]
        },
        {
            "x": -6,
            "y": -1,
            "z": 1,
            "elements": [
                "tconstruct:seared@0"
            ]
        },
        {
            "x": -5,
            "y": -1,
            "z": 1,
            "elements": [
                "tconstruct:seared@0"
            ]
        },
        {
            "x": -4,
            "y": -1,
            "z": 1,
            "elements": [
                "tconstruct:seared@0"
            ]
        },
        {
            "x": -3,
            "y": -1,
            "z": 1,
            "elements": [
                "tconstruct:seared@0"
            ]
        },
        {
            "x": 1,
            "y": 1,
            "z": -1,
            "elements": [
                "extrautils2:decorativesolid@3"
            ]
        },
        {
            "x": -2,
            "y": -1,
            "z": 1,
            "elements": [
                "tconstruct:seared@0"
            ]
        },
        {
            "x": 0,
            "y": 1,
            "z": -1,
            "elements": [
                "extrautils2:decorativesolid@3"
            ]
        },
        {
            "x": -1,
            "y": -1,
            "z": 1,
            "elements": [
                "tconstruct:seared@0"
            ]
        },
        {
            "x": 0,
            "y": -1,
            "z": 1,
            "elements": [
                "tconstruct:seared@0"
            ]
        },
        {
            "x": -1,
            "y": 1,
            "z": -1,
            "elements": [
                "extrautils2:decorativesolid@3"
            ]
        },
        {
            "x": 4,
            "y": 7,
            "z": 5,
            "elements": [
                "extrautils2:decorativesolid@3"
            ]
        },
        {
            "x": 1,
            "y": -1,
            "z": 1,
            "elements": [
                "tconstruct:seared@0"
            ]
        },
        {
            "x": 2,
            "y": -1,
            "z": 1,
            "elements": [
                "tconstruct:seared@0"
            ]
        },
        {
            "x": 3,
            "y": -1,
            "z": 1,
            "elements": [
                "tconstruct:seared@0"
            ]
        },
        {
            "x": 4,
            "y": -1,
            "z": 1,
            "elements": [
                "tconstruct:seared@0"
            ]
        },
        {
            "x": -7,
            "y": 1,
            "z": -1,
            "elements": [
                "minecraft:concrete@0"
            ]
        },
        {
            "x": -4,
            "y": 9,
            "z": 22,
            "elements": [
                "skyresources:petrifiedplanks@0"
            ]
        },
        {
            "x": -3,
            "y": 9,
            "z": 22,
            "elements": [
                "skyresources:petrifiedplanks@0"
            ]
        },
        {
            "x": -2,
            "y": 9,
            "z": 22,
            "elements": [
                "skyresources:petrifiedplanks@0"
            ]
        },
        {
            "x": -1,
            "y": 9,
            "z": 22,
            "elements": [
                "skyresources:petrifiedplanks@0"
            ]
        },
        {
            "x": 0,
            "y": 9,
            "z": 22,
            "elements": [
                "skyresources:petrifiedplanks@0"
            ]
        },
        {
            "x": -4,
            "y": 1,
            "z": 18,
            "elements": [
                "skyresources:petrifiedplanks@0"
            ]
        },
        {
            "x": 1,
            "y": 9,
            "z": 22,
            "elements": [
                "skyresources:petrifiedplanks@0"
            ]
        },
        {
            "x": 2,
            "y": 9,
            "z": 22,
            "elements": [
                "skyresources:petrifiedplanks@0"
            ]
        },
        {
            "x": -15,
            "y": 1,
            "z": -1,
            "elements": [
                "minecraft:concrete@0"
            ]
        },
        {
            "x": 3,
            "y": 9,
            "z": 22,
            "elements": [
                "skyresources:petrifiedplanks@0"
            ]
        },
        {
            "x": 4,
            "y": 9,
            "z": 22,
            "elements": [
                "skyresources:petrifiedplanks@0"
            ]
        },
        {
            "x": -15,
            "y": 0,
            "z": 1,
            "elements": [
                "minecraft:concrete@0"
            ]
        },
        {
            "x": -14,
            "y": 0,
            "z": 1,
            "elements": [
                "minecraft:concrete@0"
            ]
        },
        {
            "x": -13,
            "y": 0,
            "z": 1,
            "elements": [
                "minecraft:concrete@0"
            ]
        },
        {
            "x": -12,
            "y": 0,
            "z": 1,
            "elements": [
                "minecraft:concrete@0"
            ]
        },
        {
            "x": 4,
            "y": 1,
            "z": 18,
            "elements": [
                "skyresources:petrifiedplanks@0"
            ]
        },
        {
            "x": -11,
            "y": 0,
            "z": 1,
            "elements": [
                "minecraft:concrete@0"
            ]
        },
        {
            "x": -10,
            "y": 0,
            "z": 1,
            "elements": [
                "minecraft:concrete@0"
            ]
        },
        {
            "x": -9,
            "y": 0,
            "z": 1,
            "elements": [
                "minecraft:concrete@0"
            ]
        },
        {
            "x": -8,
            "y": 0,
            "z": 1,
            "elements": [
                "minecraft:concrete@0"
            ]
        },
        {
            "x": -4,
            "y": 8,
            "z": 5,
            "elements": [
                "extrautils2:decorativesolid@3"
            ]
        },
        {
            "x": 4,
            "y": 8,
            "z": 5,
            "elements": [
                "extrautils2:decorativesolid@3"
            ]
        },
        {
            "x": -7,
            "y": 0,
            "z": -1,
            "elements": [
                "minecraft:concrete@0"
            ]
        },
        {
            "x": -8,
            "y": 0,
            "z": -1,
            "elements": [
                "minecraft:concrete@0"
            ]
        },
        {
            "x": -9,
            "y": 0,
            "z": -1,
            "elements": [
                "minecraft:concrete@0"
            ]
        },
        {
            "x": -10,
            "y": 0,
            "z": -1,
            "elements": [
                "minecraft:concrete@0"
            ]
        },
        {
            "x": -11,
            "y": 0,
            "z": -1,
            "elements": [
                "modularmachinery:blockinputbus@2"
            ]
        },
        {
            "x": -12,
            "y": 0,
            "z": -1,
            "elements": [
                "minecraft:concrete@0"
            ]
        },
        {
            "x": -4,
            "y": 2,
            "z": 18,
            "elements": [
                "skyresources:petrifiedplanks@0"
            ]
        },
        {
            "x": -13,
            "y": 0,
            "z": -1,
            "elements": [
                "minecraft:concrete@0"
            ]
        },
        {
            "x": -14,
            "y": 0,
            "z": -1,
            "elements": [
                "minecraft:concrete@0"
            ]
        },
        {
            "x": -15,
            "y": 0,
            "z": -1,
            "elements": [
                "minecraft:concrete@0"
            ]
        },
        {
            "x": -15,
            "y": 1,
            "z": 1,
            "elements": [
                "minecraft:concrete@0"
            ]
        },
        {
            "x": 4,
            "y": 2,
            "z": 18,
            "elements": [
                "skyresources:petrifiedplanks@0"
            ]
        },
        {
            "x": -4,
            "y": 9,
            "z": 5,
            "elements": [
                "extrautils2:decorativesolid@3"
            ]
        },
        {
            "x": -7,
            "y": 1,
            "z": 1,
            "elements": [
                "minecraft:concrete@0"
            ]
        },
        {
            "x": -3,
            "y": 9,
            "z": 5,
            "elements": [
                "extrautils2:decorativesolid@3"
            ]
        },
        {
            "x": -2,
            "y": 9,
            "z": 5,
            "elements": [
                "extrautils2:decorativesolid@3"
            ]
        },
        {
            "x": -1,
            "y": 9,
            "z": 5,
            "elements": [
                "extrautils2:decorativesolid@3"
            ]
        },
        {
            "x": 4,
            "y": -1,
            "z": -1,
            "elements": [
                "tconstruct:seared@0"
            ]
        },
        {
            "x": 0,
            "y": 9,
            "z": 5,
            "elements": [
                "extrautils2:decorativesolid@3"
            ]
        },
        {
            "x": 3,
            "y": -1,
            "z": -1,
            "elements": [
                "tconstruct:seared@0"
            ]
        },
        {
            "x": 1,
            "y": 9,
            "z": 5,
            "elements": [
                "extrautils2:decorativesolid@3"
            ]
        },
        {
            "x": 2,
            "y": -1,
            "z": -1,
            "elements": [
                "tconstruct:seared@0"
            ]
        },
        {
            "x": 1,
            "y": -1,
            "z": -1,
            "elements": [
                "tconstruct:seared@0"
            ]
        },
        {
            "x": 2,
            "y": 9,
            "z": 5,
            "elements": [
                "extrautils2:decorativesolid@3"
            ]
        },
        {
            "x": 0,
            "y": -1,
            "z": -1,
            "elements": [
                "tconstruct:seared@0"
            ]
        },
        {
            "x": -1,
            "y": 1,
            "z": 1,
            "elements": [
                "extrautils2:decorativesolid@3"
            ]
        },
        {
            "x": 3,
            "y": 9,
            "z": 5,
            "elements": [
                "extrautils2:decorativesolid@3"
            ]
        },
        {
            "x": 4,
            "y": 9,
            "z": 5,
            "elements": [
                "extrautils2:decorativesolid@3"
            ]
        },
        {
            "x": 0,
            "y": 1,
            "z": 1,
            "elements": [
                "extrautils2:decorativesolid@3"
            ]
        },
        {
            "x": -1,
            "y": -1,
            "z": -1,
            "elements": [
                "tconstruct:seared@0"
            ]
        },
        {
            "x": 1,
            "y": 1,
            "z": 1,
            "elements": [
                "extrautils2:decorativesolid@3"
            ]
        },
        {
            "x": -2,
            "y": -1,
            "z": -1,
            "elements": [
                "tconstruct:seared@0"
            ]
        },
        {
            "x": -3,
            "y": -1,
            "z": -1,
            "elements": [
                "tconstruct:seared@0"
            ]
        },
        {
            "x": -4,
            "y": -1,
            "z": -1,
            "elements": [
                "tconstruct:seared@0"
            ]
        },
        {
            "x": -5,
            "y": -1,
            "z": -1,
            "elements": [
                "tconstruct:seared@0"
            ]
        },
        {
            "x": -6,
            "y": -1,
            "z": -1,
            "elements": [
                "tconstruct:seared@0"
            ]
        },
        {
            "x": -7,
            "y": -1,
            "z": -1,
            "elements": [
                "tconstruct:seared@0"
            ]
        },
        {
            "x": -8,
            "y": -1,
            "z": -1,
            "elements": [
                "tconstruct:seared@0"
            ]
        },
        {
            "x": -9,
            "y": -1,
            "z": -1,
            "elements": [
                "tconstruct:seared@0"
            ]
        },
        {
            "x": -10,
            "y": -1,
            "z": -1,
            "elements": [
                "tconstruct:seared@0"
            ]
        },
        {
            "x": -11,
            "y": -1,
            "z": -1,
            "elements": [
                "tconstruct:seared@0"
            ]
        },
        {
            "x": -12,
            "y": -1,
            "z": -1,
            "elements": [
                "tconstruct:seared@0"
            ]
        },
        {
            "x": -4,
            "y": 3,
            "z": 18,
            "elements": [
                "skyresources:petrifiedplanks@0"
            ]
        },
        {
            "x": -13,
            "y": -1,
            "z": -1,
            "elements": [
                "tconstruct:seared@0"
            ]
        },
        {
            "x": -14,
            "y": -1,
            "z": -1,
            "elements": [
                "tconstruct:seared@0"
            ]
        },
        {
            "x": -15,
            "y": -1,
            "z": -1,
            "elements": [
                "tconstruct:seared@0"
            ]
        },
        {
            "x": -16,
            "y": -1,
            "z": -1,
            "elements": [
                "tconstruct:seared@0"
            ]
        },
