{
    "registryname": "astrological_column",
    "localizedname": "higanbana.modularmachinery.astrological_column.name",
    "requires-blueprint": true,
    "color": "CDC4C6",
    "modifiers": [
        {
            "elements": "contenttweaker:star_liquid@0",
            "x": 0,
            "y": 1,
            "z": 1,
            "description": "核心液体使用星辰液将有双倍产出，但会使得合成时间翻倍",
            "modifier": [
                {
                    "io": "output",
                    "target": "item",
                    "operation": 1,
                    "multiplier": 2.0
                },
                {
                    "io":"input",
                    "target": "duration",
                    "operation": 1,
                    "multiplier": 1.5
                }
            ]
        },
        {
            "elements": "astralsorcery:blockcelestialcollectorcrystal@0",
            "x": 0,
            "y": 2,
            "z": 1,
            "description": "核心使用聚能水晶, 合成所需星能减半",
            "modifier": [
                {
                    "io":"input",
                    "target": "gugu-utils:starlight",
                    "operation": 1,
                    "multiplier": 0.5
                }
            ]
        }
    ],
    "parts": [
        {
            "x": -1,
            "y": 0,
            "z": 0,
            "elements": [
                "astralsorcery:blockmarble@6"
            ]
        },
        {
            "x": -1,
            "y": 0,
            "z": 1,
            "elements": [
                "modularmachinery:blockcasing@5"
            ]
        },
        {
            "x": 0,
            "y": 2,
            "z": 2,
            "elements": [
                "inspirations:glass_trapdoor@5"
            ]
        },
        {
            "x": 1,
            "y": 2,
            "z": 1,
            "elements": [
                "inspirations:glass_trapdoor@7"
            ]
        },
        {
            "x": 0,
            "y": 0,
            "z": 1,
            "elements": [
                "modularmachinery:blockcasing@5"
            ]
        },
        {
            "x": 1,
            "y": 0,
            "z": 0,
            "elements": [
                "astralsorcery:blockmarble@6"
            ]
        },
        {
            "x": -1,
            "y": 0,
            "z": 2,
            "elements": [
                "astralsorcery:blockmarble@6"
            ]
        },
        {
            "x": 1,
            "y": 2,
            "z": 2,
            "elements": [
                "chisel:marblepillar@12"
            ]
        },
        {
            "x": 1,
            "y": 0,
            "z": 1,
            "elements": [
                "modularmachinery:blockcasing@5"
            ]
        },
        {
            "x": 0,
            "y": 0,
            "z": 2,
            "elements": [
                "modularmachinery:blockcasing@5"
            ]
        },
        {
            "x": 1,
            "y": 0,
            "z": 2,
            "elements": [
                "astralsorcery:blockmarble@6"
            ]
        },
        {
            "x": -1,
            "y": 3,
            "z": 0,
            "elements": [
                "chisel:marblepillar@12"
            ]
        },
        {
            "x": -1,
            "y": 3,
            "z": 1,
            "elements": [
                "astralsorcery:blockmarbleslab@8"
            ]
        },
        {
            "x": 0,
            "y": 3,
            "z": 1,
            "elements": [
                "inspirations:glass_trapdoor@1"
            ]
        },
        {
            "x": 1,
            "y": 3,
            "z": 0,
            "elements": [
                "chisel:marblepillar@12"
            ]
        },
        {
            "x": -1,
            "y": 1,
            "z": 0,
            "elements": [
                "chisel:marblepillar@12"
            ]
        },
        {
            "x": -1,
            "y": 3,
            "z": 2,
            "elements": [
                "chisel:marblepillar@12"
            ]
        },
        {
            "x": 1,
            "y": 3,
            "z": 1,
            "elements": [
                "astralsorcery:blockmarbleslab@8"
            ]
        },
        {
            "x": 0,
            "y": 1,
            "z": 0,
            "elements": [
                "astralsorcery:blockmarbleslab@0"
            ]
        },
        {
            "x": -1,
            "y": 1,
            "z": 1,
            "elements": [
                "astralsorcery:blockmarbleslab@0"
            ]
        },
        {
            "x": 1,
            "y": 3,
            "z": 2,
            "elements": [
                "chisel:marblepillar@12"
            ]
        },
        {
            "x": 0,
            "y": 1,
            "z": 1,
            "elements": [
                "astralsorcery:fluidblockliquidstarlight@0"
            ]
        },
        {
            "x": 1,
            "y": 1,
            "z": 0,
            "elements": [
                "chisel:marblepillar@12"
            ]
        },
        {
            "x": -1,
            "y": 1,
            "z": 2,
            "elements": [
                "chisel:marblepillar@12"
            ]
        },
        {
            "x": 0,
            "y": 1,
            "z": 2,
            "elements": [
                "astralsorcery:blockmarbleslab@0"
            ]
        },
        {
            "x": 1,
            "y": 1,
            "z": 1,
            "elements": [
                "astralsorcery:blockmarbleslab@0"
            ]
        },
        {
            "x": 1,
            "y": 1,
            "z": 2,
            "elements": [
                "chisel:marblepillar@12"
            ]
        },
        {
            "x": -1,
            "y": 4,
            "z": 0,
            "elements": [
                "astralsorcery:blockmarblestairs@4"
            ]
        },
        {
            "x": -1,
            "y": 4,
            "z": 1,
            "elements": [
                "astralsorcery:blockmarblestairs@4"
            ]
        },
        {
            "x": 0,
            "y": 4,
            "z": 0,
            "elements": [
                "astralsorcery:blockmarblestairs@6"
            ]
        },
        {
            "x": -1,
            "y": 2,
            "z": 0,
            "elements": [
                "chisel:marblepillar@12"
            ]
        },
        {
            "x": -1,
            "y": 4,
            "z": 2,
            "elements": [
                "astralsorcery:blockmarblestairs@4"
            ]
        },
        {
            "x": 0,
            "y": 4,
            "z": 1,
            "elements": [
                "gugu-utils:environmenthatch@0"
            ]
        },
        {
            "x": 1,
            "y": 4,
            "z": 0,
            "elements": [
                "astralsorcery:blockmarblestairs@5"
            ]
        },
        {
            "x": -1,
            "y": 2,
            "z": 1,
            "elements": [
                "inspirations:glass_trapdoor@6"
            ]
        },
        {
            "x": 0,
            "y": 4,
            "z": 2,
            "elements": [
                "astralsorcery:blockmarblestairs@7"
            ]
        },
        {
            "x": 1,
            "y": 4,
            "z": 1,
            "elements": [
                "astralsorcery:blockmarblestairs@5"
            ]
        },
        {
            "x": 0,
            "y": 2,
            "z": 0,
            "elements": [
                "inspirations:glass_trapdoor@4"
            ]
        },
        {
            "x": -1,
            "y": 2,
            "z": 2,
            "elements": [
                "chisel:marblepillar@12"
            ]
        },
        {
            "x": 1,
            "y": 4,
            "z": 2,
            "elements": [
                "astralsorcery:blockmarblestairs@7"
            ]
        },
        {
            "x": 0,
            "y": 2,
            "z": 1,
            "elements": [
                "astralsorcery:blockcollectorcrystal@0"
            ]
        },
        {
            "x": 1,
            "y": 2,
            "z": 0,
            "elements": [
                "chisel:marblepillar@12"
            ]
        }
    ]}