{
    "registryname": "machine6",
    "localizedname": "龙城粒子对撞机",
	"requires-blueprint": true,
	"color":"9966FF",
    "parts": [
        {
            "x": -1,
            "y": 0,
            "z": 0,
            "elements": [
                "modularmachinery:blockoutputbus@0"
            ]
        },
        {
            "x": 4,
            "y": 8,
            "z": 4,
            "elements": [
                "bloodmagic:demon_extras@0"
            ]
        },
        {
            "x": 12,
            "y": 8,
            "z": 4,
            "elements": [
                "bloodmagic:demon_extras@0"
            ]
        },
        {
            "x": 13,
            "y": 0,
            "z": 0,
            "elements": [
                "modularmachinery:blockcasing@0"
            ]
        },
        {
            "x": -14,
            "y": 0,
            "z": 0,
            "elements": [
                "modularmachinery:blockcasing@0"
            ]
        },
        {
            "x": -12,
            "y": 9,
            "z": 4,
            "elements": [
                "minecraft:purpur_block@0"
            ]
        },
        {
            "x": -11,
            "y": 9,
            "z": 4,
            "elements": [
                "minecraft:purpur_block@0"
            ]
        },
        {
            "x": 13,
            "y": -1,
            "z": 0,
            "elements": [
                "modularmachinery:blockcasing@0"
            ]
        },
        {
            "x": -14,
            "y": 1,
            "z": 0,
            "elements": [
                "modularmachinery:blockcasing@0"
            ]
        },
        {
            "x": -10,
            "y": 9,
            "z": 4,
            "elements": [
                "minecraft:purpur_block@0"
            ]
        },
        {
            "x": -9,
            "y": 9,
            "z": 4,
            "elements": [
                "minecraft:purpur_block@0"
            ]
        },
        {
            "x": -8,
            "y": 9,
            "z": 4,
            "elements": [
                "minecraft:purpur_block@0"
            ]
        },
        {
            "x": -7,
            "y": 9,
            "z": 4,
            "elements": [
                "minecraft:purpur_block@0"
            ]
        },
        {
            "x": -6,
            "y": 9,
            "z": 4,
            "elements": [
                "minecraft:purpur_block@0"
            ]
        },
        {
            "x": 3,
            "y": -1,
            "z": 0,
            "elements": [
                "minecraft:end_stone@0"
            ]
        },
        {
            "x": 2,
            "y": -1,
            "z": 0,
            "elements": [
                "minecraft:end_stone@0"
            ]
        },
        {
            "x": 1,
            "y": -1,
            "z": 0,
            "elements": [
                "minecraft:end_stone@0"
            ]
        },
        {
            "x": 0,
            "y": -1,
            "z": 0,
            "elements": [
                "minecraft:end_stone@0"
            ]
        },
        {
            "x": -1,
            "y": -1,
            "z": 0,
            "elements": [
                "minecraft:end_stone@0"
            ]
        },
        {
            "x": 5,
            "y": 9,
            "z": 4,
            "elements": [
                "minecraft:purpur_block@0"
            ]
        },
        {
            "x": -2,
            "y": -1,
            "z": 0,
            "elements": [
                "minecraft:end_stone@0"
            ]
        },
        {
            "x": 6,
            "y": 9,
            "z": 4,
            "elements": [
                "minecraft:purpur_block@0"
            ]
        },
        {
            "x": -3,
            "y": -1,
            "z": 0,
            "elements": [
                "minecraft:end_stone@0"
            ]
        },
        {
            "x": 7,
            "y": 9,
            "z": 4,
            "elements": [
                "minecraft:purpur_block@0"
            ]
        },
        {
            "x": -4,
            "y": -1,
            "z": 0,
            "elements": [
                "minecraft:end_stone@0"
            ]
        },
        {
            "x": 8,
            "y": 9,
            "z": 4,
            "elements": [
                "minecraft:purpur_block@0"
            ]
        },
        {
            "x": 9,
            "y": 9,
            "z": 4,
            "elements": [
                "minecraft:purpur_block@0"
            ]
        },
        {
            "x": 10,
            "y": 9,
            "z": 4,
            "elements": [
                "minecraft:purpur_block@0"
            ]
        },
        {
            "x": 11,
            "y": 9,
            "z": 4,
            "elements": [
                "minecraft:purpur_block@0"
            ]
        },
        {
            "x": 13,
            "y": 1,
            "z": 0,
            "elements": [
                "modularmachinery:blockcasing@0"
            ]
        },
        {
            "x": -14,
            "y": -1,
            "z": 0,
            "elements": [
                "modularmachinery:blockcasing@0"
            ]
        },
        {
            "x": 13,
            "y": -2,
            "z": 0,
            "elements": [
                "modularmachinery:blockcasing@0"
            ]
        },
        {
            "x": -14,
            "y": 2,
            "z": 0,
            "elements": [
                "modularmachinery:blockcasing@0"
            ]
        },
        {
            "x": 3,
            "y": -2,
            "z": 0,
            "elements": [
                "modularmachinery:blockcasing@0"
            ]
        },
        {
            "x": -4,
            "y": -2,
            "z": 0,
            "elements": [
                "modularmachinery:blockcasing@0"
            ]
        },
        {
            "x": 13,
            "y": 2,
            "z": 0,
            "elements": [
                "modularmachinery:blockcasing@0"
            ]
        },
        {
            "x": -14,
            "y": -2,
            "z": 0,
            "elements": [
                "modularmachinery:blockcasing@0"
            ]
        },
        {
            "x": 13,
            "y": -3,
            "z": 0,
            "elements": [
                "modularmachinery:blockcasing@0"
            ]
        },
        {
            "x": -14,
            "y": 3,
            "z": 0,
            "elements": [
                "modularmachinery:blockcasing@0"
            ]
        },
        {
            "x": 3,
            "y": -3,
            "z": 0,
            "elements": [
                "modularmachinery:blockcasing@0"
            ]
        },
        {
            "x": -4,
            "y": 3,
            "z": 0,
            "elements": [
                "minecraft:end_stone@0"
            ]
        },
        {
            "x": 3,
            "y": 3,
            "z": 0,
            "elements": [
                "minecraft:end_stone@0"
            ]
        },
        {
            "x": -4,
            "y": -3,
            "z": 0,
            "elements": [
                "modularmachinery:blockcasing@0"
            ]
        },
        {
            "x": 13,
            "y": 3,
            "z": 0,
            "elements": [
                "modularmachinery:blockcasing@0"
            ]
        },
        {
            "x": -14,
            "y": -3,
            "z": 0,
            "elements": [
                "modularmachinery:blockcasing@0"
            ]
        },
        {
            "x": 13,
            "y": -4,
            "z": 0,
            "elements": [
                "modularmachinery:blockcasing@0"
            ]
        },
        {
            "x": -14,
            "y": 4,
            "z": 0,
            "elements": [
                "modularmachinery:blockcasing@0"
            ]
        },
        {
            "x": 3,
            "y": -4,
            "z": 0,
            "elements": [
                "modularmachinery:blockcasing@0"
            ]
        },
        {
            "x": -4,
            "y": 4,
            "z": 0,
            "elements": [
                "modularmachinery:blockcasing@0"
            ]
        },
        {
            "x": 3,
            "y": 4,
            "z": 0,
            "elements": [
                "modularmachinery:blockcasing@0"
            ]
        },
        {
            "x": -4,
            "y": -4,
            "z": 0,
            "elements": [
                "modularmachinery:blockcasing@0"
            ]
        },
        {
            "x": 13,
            "y": 4,
            "z": 0,
            "elements": [
                "modularmachinery:blockcasing@0"
            ]
        },
        {
            "x": -14,
            "y": -4,
            "z": 0,
            "elements": [
                "modularmachinery:blockcasing@0"
            ]
        },
        {
            "x": 13,
            "y": -5,
            "z": 0,
            "elements": [
                "astralsorcery:blockmarble@6"
            ]
        },
        {
            "x": -14,
            "y": 5,
            "z": 0,
            "elements": [
                "modularmachinery:blockcasing@0"
            ]
        },
        {
            "x": 3,
            "y": -5,
            "z": 0,
            "elements": [
                "astralsorcery:blockmarble@6"
            ]
        },
        {
            "x": -4,
            "y": 5,
            "z": 0,
            "elements": [
                "modularmachinery:blockcasing@0"
            ]
        },
        {
            "x": 3,
            "y": 5,
            "z": 0,
            "elements": [
                "modularmachinery:blockcasing@0"
            ]
        },
        {
            "x": -4,
            "y": -5,
            "z": 0,
            "elements": [
                "astralsorcery:blockmarble@6"
            ]
        },
        {
            "x": 13,
            "y": 5,
            "z": 0,
            "elements": [
                "modularmachinery:blockcasing@0"
            ]
        },
        {
            "x": -14,
            "y": -5,
            "z": 0,
            "elements": [
                "astralsorcery:blockmarble@6"
            ]
        },
        {
            "x": -14,
            "y": 6,
            "z": 0,
            "elements": [
                "astralsorcery:blockmarble@6"
            ]
        },
        {
            "x": 12,
            "y": -6,
            "z": 0,
            "elements": [
                "bloodmagic:demon_extras@1"
            ]
        },
        {
            "x": 4,
            "y": -6,
            "z": 0,
            "elements": [
                "bloodmagic:demon_extras@1"
            ]
        },
        {
            "x": -4,
            "y": 6,
            "z": 0,
            "elements": [
                "astralsorcery:blockmarble@6"
            ]
        },
        {
            "x": 3,
            "y": 6,
            "z": 0,
            "elements": [
                "astralsorcery:blockmarble@6"
            ]
        },
        {
            "x": -5,
            "y": -6,
            "z": 0,
            "elements": [
                "bloodmagic:demon_extras@1"
            ]
        },
        {
            "x": -13,
            "y": -6,
            "z": 0,
            "elements": [
                "bloodmagic:demon_extras@1"
            ]
        },
        {
            "x": 13,
            "y": 6,
            "z": 0,
            "elements": [
                "astralsorcery:blockmarble@6"
            ]
        },
        {
            "x": -14,
            "y": 7,
            "z": 0,
            "elements": [
                "bloodmagic:demon_extras@1"
            ]
        },
        {
            "x": 11,
            "y": -7,
            "z": 0,
            "elements": [
                "bloodmagic:demon_extras@0"
            ]
        },
        {
            "x": 5,
            "y": -7,
            "z": 0,
            "elements": [
                "bloodmagic:demon_extras@0"
            ]
        },
        {
            "x": -4,
            "y": 7,
            "z": 0,
            "elements": [
                "bloodmagic:demon_extras@1"
            ]
        },
        {
            "x": 3,
            "y": 7,
            "z": 0,
            "elements": [
                "bloodmagic:demon_extras@1"
            ]
        },
        {
            "x": -6,
            "y": -7,
            "z": 0,
            "elements": [
                "bloodmagic:demon_extras@0"
            ]
        },
        {
            "x": -12,
            "y": -7,
            "z": 0,
            "elements": [
                "bloodmagic:demon_extras@0"
            ]
        },
        {
            "x": 13,
            "y": 7,
            "z": 0,
            "elements": [
                "bloodmagic:demon_extras@1"
            ]
        },
        {
            "x": -13,
            "y": 8,
            "z": 0,
            "elements": [
                "bloodmagic:demon_extras@0"
            ]
        },
        {
            "x": 10,
            "y": -8,
            "z": 0,
            "elements": [
                "minecraft:purpur_block@0"
            ]
        },
        {
            "x": 9,
            "y": -8,
            "z": 0,
            "elements": [
                "minecraft:purpur_block@0"
            ]
        },
        {
            "x": 8,
            "y": -8,
            "z": 0,
            "elements": [
                "minecraft:purpur_block@0"
            ]
        },
        {
            "x": 7,
            "y": -8,
            "z": 0,
            "elements": [
                "minecraft:purpur_block@0"
            ]
        },
        {
            "x": 6,
            "y": -8,
            "z": 0,
            "elements": [
                "minecraft:purpur_block@0"
            ]
        },
        {
            "x": -5,
            "y": 8,
            "z": 0,
            "elements": [
                "bloodmagic:demon_extras@0"
            ]
        },
        {
            "x": 4,
            "y": 8,
            "z": 0,
            "elements": [
                "bloodmagic:demon_extras@0"
            ]
        },
        {
            "x": -7,
            "y": -8,
            "z": 0,
            "elements": [
                "minecraft:purpur_block@0"
            ]
        },
        {
            "x": -8,
            "y": -8,
            "z": 0,
            "elements": [
                "minecraft:purpur_block@0"
            ]
        },
        {
            "x": -9,
            "y": -8,
            "z": 0,
            "elements": [
                "minecraft:purpur_block@0"
            ]
        },
        {
            "x": -10,
            "y": -8,
            "z": 0,
            "elements": [
                "minecraft:purpur_block@0"
            ]
        },
        {
            "x": -11,
            "y": -8,
            "z": 0,
            "elements": [
                "minecraft:purpur_block@0"
            ]
        },
        {
            "x": 12,
            "y": 8,
            "z": 0,
            "elements": [
                "bloodmagic:demon_extras@0"
            ]
        },
        {
            "x": -12,
            "y": 9,
            "z": 0,
            "elements": [
                "minecraft:purpur_block@0"
            ]
        },
        {
            "x": -11,
            "y": 9,
            "z": 0,
            "elements": [
                "minecraft:purpur_block@0"
            ]
        },
        {
            "x": -10,
            "y": 9,
            "z": 0,
            "elements": [
                "minecraft:purpur_block@0"
            ]
        },
        {
            "x": -9,
            "y": 9,
            "z": 0,
            "elements": [
                "minecraft:purpur_block@0"
            ]
        },
        {
            "x": -8,
            "y": 9,
            "z": 0,
            "elements": [
                "minecraft:purpur_block@0"
            ]
        },
        {
            "x": -7,
            "y": 9,
            "z": 0,
            "elements": [
                "minecraft:purpur_block@0"
            ]
        },
        {
            "x": -6,
            "y": 9,
            "z": 0,
            "elements": [
                "minecraft:purpur_block@0"
            ]
        },
        {
            "x": 5,
            "y": 9,
            "z": 0,
            "elements": [
                "minecraft:purpur_block@0"
            ]
        },
        {
            "x": 6,
            "y": 9,
            "z": 0,
            "elements": [
                "minecraft:purpur_block@0"
            ]
        },
        {
            "x": 7,
            "y": 9,
            "z": 0,
            "elements": [
                "minecraft:purpur_block@0"
            ]
        },
        {
            "x": 8,
            "y": 9,
            "z": 0,
            "elements": [
                "minecraft:purpur_block@0"
            ]
        },
        {
            "x": 9,
            "y": 9,
            "z": 0,
            "elements": [
                "minecraft:purpur_block@0"
            ]
        },
        {
            "x": 10,
            "y": 9,
            "z": 0,
            "elements": [
                "minecraft:purpur_block@0"
            ]
        },
        {
            "x": 11,
            "y": 9,
            "z": 0,
            "elements": [
                "minecraft:purpur_block@0"
            ]
        },
        {
            "x": 12,
            "y": 7,
            "z": -5,
            "elements": [
                "bloodmagic:demon_extras@1"
            ]
        },
        {
            "x": 11,
            "y": 7,
            "z": -5,
            "elements": [
                "bloodmagic:demon_extras@1"
            ]
        },
        {
            "x": 10,
            "y": 7,
            "z": -5,
            "elements": [
                "bloodmagic:demon_extras@1"
            ]
        },
        {
            "x": -11,
            "y": -7,
            "z": 5,
            "elements": [
                "bloodmagic:demon_extras@0"
            ]
        },
        {
            "x": 9,
            "y": 7,
            "z": -5,
            "elements": [
                "bloodmagic:demon_extras@1"
            ]
        },
        {
            "x": -10,
            "y": -7,
            "z": 5,
            "elements": [
                "bloodmagic:demon_extras@0"
            ]
        },
        {
            "x": -9,
            "y": -7,
            "z": 5,
            "elements": [
                "bloodmagic:demon_extras@0"
            ]
        },
        {
            "x": 8,
            "y": 7,
            "z": -5,
            "elements": [
                "bloodmagic:demon_extras@1"
            ]
        },
        {
            "x": 7,
            "y": 7,
            "z": -5,
            "elements": [
                "bloodmagic:demon_extras@1"
            ]
        },
        {
            "x": -8,
            "y": -7,
            "z": 5,
            "elements": [
                "bloodmagic:demon_extras@0"
            ]
        },
        {
            "x": 6,
            "y": 7,
            "z": -5,
            "elements": [
                "bloodmagic:demon_extras@1"
            ]
        },
        {
            "x": -7,
            "y": -7,
            "z": 5,
            "elements": [
                "bloodmagic:demon_extras@0"
            ]
        },
        {
            "x": 5,
            "y": 7,
            "z": -5,
            "elements": [
                "bloodmagic:demon_extras@1"
            ]
        },
        {
            "x": 4,
            "y": 7,
            "z": -5,
            "elements": [
                "bloodmagic:demon_extras@1"
            ]
        },
        {
            "x": -5,
            "y": 7,
            "z": -5,
            "elements": [
                "bloodmagic:demon_extras@1"
            ]
        },
        {
            "x": -6,
            "y": 7,
            "z": -5,
            "elements": [
                "bloodmagic:demon_extras@1"
            ]
        },
        {
            "x": 6,
            "y": -7,
            "z": 5,
            "elements": [
                "bloodmagic:demon_extras@0"
            ]
        },
        {
            "x": -7,
            "y": 7,
            "z": -5,
            "elements": [
                "bloodmagic:demon_extras@1"
            ]
        },
        {
            "x": 7,
            "y": -7,
            "z": 5,
            "elements": [
                "bloodmagic:demon_extras@0"
            ]
        },
        {
            "x": -8,
            "y": 7,
            "z": -5,
            "elements": [
                "bloodmagic:demon_extras@1"
            ]
        },
        {
            "x": -9,
            "y": 7,
            "z": -5,
            "elements": [
                "bloodmagic:demon_extras@1"
            ]
        },
        {
            "x": 8,
            "y": -7,
            "z": 5,
            "elements": [
                "bloodmagic:demon_extras@0"
            ]
        },
        {
            "x": 9,
            "y": -7,
            "z": 5,
            "elements": [
                "bloodmagic:demon_extras@0"
            ]
        },
        {
            "x": -10,
            "y": 7,
            "z": -5,
            "elements": [
                "bloodmagic:demon_extras@1"
            ]
        },
        {
            "x": 10,
            "y": -7,
            "z": 5,
            "elements": [
                "bloodmagic:demon_extras@0"
            ]
        },
        {
            "x": -11,
            "y": 7,
            "z": -5,
            "elements": [
                "bloodmagic:demon_extras@1"
            ]
        },
        {
            "x": -12,
            "y": 7,
            "z": -5,
            "elements": [
                "bloodmagic:demon_extras@1"
            ]
        },
        {
            "x": -13,
            "y": 7,
            "z": -5,
            "elements": [
                "bloodmagic:demon_extras@1"
            ]
        },
        {
            "x": -13,
            "y": -6,
            "z": 5,
            "elements": [
                "bloodmagic:demon_extras@1"
            ]
        },
        {
            "x": 12,
            "y": 6,
            "z": -5,
            "elements": [
                "bloodarsenal:blood_infused_iron_block@0"
            ]
        },
        {
            "x": 11,
            "y": 6,
            "z": -5,
            "elements": [
                "astralsorcery:blockmarble@6"
            ]
        },
        {
            "x": -12,
            "y": -6,
            "z": 5,
            "elements": [
                "bloodmagic:demon_extras@1"
            ]
        },
        {
            "x": 10,
            "y": 6,
            "z": -5,
            "elements": [
                "astralsorcery:blockmarble@6"
            ]
        },
        {
            "x": 9,
            "y": 6,
            "z": -5,
            "elements": [
                "astralsorcery:blockmarble@6"
            ]
        },
        {
            "x": 8,
            "y": 6,
            "z": -5,
            "elements": [
                "astralsorcery:blockmarble@6"
            ]
        },
        {
            "x": 7,
            "y": 6,
            "z": -5,
            "elements": [
                "astralsorcery:blockmarble@6"
            ]
        },
        {
            "x": 6,
            "y": 6,
            "z": -5,
            "elements": [
                "astralsorcery:blockmarble@6"
            ]
        },
        {
            "x": 5,
            "y": 6,
            "z": -5,
            "elements": [
                "astralsorcery:blockmarble@6"
            ]
        },
        {
            "x": -6,
            "y": -6,
            "z": 5,
            "elements": [
                "bloodmagic:demon_extras@1"
            ]
        },
        {
            "x": -5,
            "y": -6,
            "z": 5,
            "elements": [
                "bloodmagic:demon_extras@1"
            ]
        },
        {
            "x": 4,
            "y": 6,
            "z": -5,
            "elements": [
                "bloodarsenal:blood_infused_iron_block@0"
            ]
        },
        {
            "x": -5,
            "y": 6,
            "z": -5,
            "elements": [
                "bloodarsenal:blood_infused_iron_block@0"
            ]
        },
        {
            "x": 4,
            "y": -6,
            "z": 5,
            "elements": [
                "bloodmagic:demon_extras@1"
            ]
        },
        {
            "x": 5,
            "y": -6,
            "z": 5,
            "elements": [
                "bloodmagic:demon_extras@1"
            ]
        },
        {
            "x": -6,
            "y": 6,
            "z": -5,
            "elements": [
                "astralsorcery:blockmarble@6"
            ]
        },
        {
            "x": -7,
            "y": 6,
            "z": -5,
            "elements": [
                "astralsorcery:blockmarble@6"
            ]
        },
        {
            "x": -8,
            "y": 6,
            "z": -5,
            "elements": [
                "astralsorcery:blockmarble@6"
            ]
        },
        {
            "x": -9,
            "y": 6,
            "z": -5,
            "elements": [
                "astralsorcery:blockmarble@6"
            ]
        },
        {
            "x": -10,
            "y": 6,
            "z": -5,
            "elements": [
                "astralsorcery:blockmarble@6"
            ]
        },
        {
            "x": -11,
            "y": 6,
            "z": -5,
            "elements": [
                "astralsorcery:blockmarble@6"
            ]
        },
        {
            "x": 11,
            "y": -6,
            "z": 5,
            "elements": [
                "bloodmagic:demon_extras@1"
            ]
        },
        {
            "x": -12,
            "y": 6,
            "z": -5,
            "elements": [
                "astralsorcery:blockmarble@6"
            ]
        },
        {
            "x": -13,
            "y": 6,
            "z": -5,
            "elements": [
                "bloodarsenal:blood_infused_iron_block@0"
            ]
        },
        {
            "x": 12,
            "y": -6,
            "z": 5,
            "elements": [
                "bloodmagic:demon_extras@1"
            ]
        },
        {
            "x": -14,
            "y": -5,
            "z": 5,
            "elements": [
                "astralsorcery:blockmarble@6"
            ]
        },
        {
            "x": 12,
            "y": 5,
            "z": -5,
            "elements": [
                "naturesaura:infused_stone@0"
            ]
        },
        {
            "x": 11,
            "y": 5,
            "z": -5,
            "elements": [
                "modularmachinery:blockcasing@0"
            ]
        },
        {
            "x": -12,
            "y": -5,
            "z": 5,
            "elements": [
                "minecraft:sea_lantern@0"
            ]
        },
        {
            "x": 10,
            "y": 5,
            "z": -5,
            "elements": [
                "modularmachinery:blockcasing@0"
            ]
        },
        {
            "x": 9,
            "y": 5,
            "z": -5,
            "elements": [
                "modularmachinery:blockcasing@0"
            ]
        },
        {
            "x": 8,
            "y": 5,
            "z": -5,
            "elements": [
                "modularmachinery:blockcasing@0"
            ]
        },
        {
            "x": 7,
            "y": 5,
            "z": -5,
            "elements": [
                "modularmachinery:blockcasing@0"
            ]
        },
        {
            "x": 6,
            "y": 5,
            "z": -5,
            "elements": [
                "modularmachinery:blockcasing@0"
            ]
        },
        {
            "x": 5,
            "y": 5,
            "z": -5,
            "elements": [
                "modularmachinery:blockcasing@0"
            ]
        },
        {
            "x": -6,
            "y": -5,
            "z": 5,
            "elements": [
                "minecraft:sea_lantern@0"
            ]
        },
        {
            "x": 4,
            "y": 5,
            "z": -5,
            "elements": [
                "naturesaura:infused_stone@0"
            ]
        },
        {
            "x": -4,
            "y": -5,
            "z": 5,
            "elements": [
                "astralsorcery:blockmarble@6"
            ]
        },
        {
            "x": 3,
            "y": -5,
            "z": 5,
            "elements": [
                "astralsorcery:blockmarble@6"
            ]
        },
        {
            "x": -5,
            "y": 5,
            "z": -5,
            "elements": [
                "naturesaura:infused_stone@0"
            ]
        },
        {
            "x": 5,
            "y": -5,
            "z": 5,
            "elements": [
                "minecraft:sea_lantern@0"
            ]
        },
        {
            "x": -6,
            "y": 5,
            "z": -5,
            "elements": [
                "modularmachinery:blockcasing@0"
            ]
        },
        {
            "x": -7,
            "y": 5,
            "z": -5,
            "elements": [
                "modularmachinery:blockcasing@0"
            ]
        },
        {
            "x": -8,
            "y": 5,
            "z": -5,
            "elements": [
                "modularmachinery:blockcasing@0"
            ]
        },
        {
            "x": -9,
            "y": 5,
            "z": -5,
            "elements": [
                "modularmachinery:blockcasing@0"
            ]
        },
        {
            "x": -10,
            "y": 5,
            "z": -5,
            "elements": [
                "modularmachinery:blockcasing@0"
            ]
        },
        {
            "x": -11,
            "y": 5,
            "z": -5,
            "elements": [
                "modularmachinery:blockcasing@0"
            ]
        },
        {
            "x": 11,
            "y": -5,
            "z": 5,
            "elements": [
                "minecraft:sea_lantern@0"
            ]
        },
        {
            "x": -12,
            "y": 5,
            "z": -5,
            "elements": [
                "modularmachinery:blockcasing@0"
            ]
        },
        {
            "x": -13,
            "y": 5,
            "z": -5,
            "elements": [
                "naturesaura:infused_stone@0"
            ]
        },
        {
            "x": 13,
            "y": -5,
            "z": 5,
            "elements": [
                "astralsorcery:blockmarble@6"
            ]
        },
        {
            "x": -14,
            "y": -4,
            "z": 5,
            "elements": [
                "modularmachinery:blockcasing@0"
            ]
        },
        {
            "x": 12,
            "y": 4,
            "z": -5,
            "elements": [
                "naturesaura:infused_stone@0"
            ]
        },
        {
            "x": 11,
            "y": 4,
            "z": -5,
            "elements": [
                "modularmachinery:blockcasing@0"
            ]
        },
        {
            "x": 10,
            "y": 4,
            "z": -5,
            "elements": [
                "modularmachinery:blockcasing@0"
            ]
        },
        {
            "x": 9,
            "y": 4,
            "z": -5,
            "elements": [
                "modularmachinery:blockcasing@0"
            ]
        },
        {
            "x": 8,
            "y": 4,
            "z": -5,
            "elements": [
                "modularmachinery:blockcasing@0"
            ]
        },
        {
            "x": 7,
            "y": 4,
            "z": -5,
            "elements": [
                "modularmachinery:blockcasing@0"
            ]
        },
        {
            "x": 6,
            "y": 4,
            "z": -5,
            "elements": [
                "modularmachinery:blockcasing@0"
            ]
        },
        {
            "x": 5,
            "y": 4,
            "z": -5,
            "elements": [
                "modularmachinery:blockcasing@0"
            ]
        },
        {
            "x": 4,
            "y": 4,
            "z": -5,
            "elements": [
                "naturesaura:infused_stone@0"
            ]
        },
        {
            "x": -4,
            "y": -4,
            "z": 5,
            "elements": [
                "modularmachinery:blockcasing@0"
            ]
        },
        {
            "x": 3,
            "y": -4,
            "z": 5,
            "elements": [
                "modularmachinery:blockcasing@0"
            ]
        },
        {
            "x": -5,
            "y": 4,
            "z": -5,
            "elements": [
                "naturesaura:infused_stone@0"
            ]
        },
        {
            "x": -6,
            "y": 4,
            "z": -5,
            "elements": [
                "modularmachinery:blockcasing@0"
            ]
        },
        {
            "x": -7,
            "y": 4,
            "z": -5,
            "elements": [
                "modularmachinery:blockcasing@0"
            ]
        },
        {
            "x": -8,
            "y": 4,
            "z": -5,
            "elements": [
                "modularmachinery:blockcasing@0"
            ]
        },
        {
            "x": -9,
            "y": 4,
            "z": -5,
            "elements": [
                "modularmachinery:blockcasing@0"
            ]
        },
        {
            "x": -10,
            "y": 4,
            "z": -5,
            "elements": [
                "modularmachinery:blockcasing@0"
            ]
        },
        {
            "x": -11,
            "y": 4,
            "z": -5,
            "elements": [
                "modularmachinery:blockcasing@0"
            ]
        },
        {
            "x": -12,
            "y": 4,
            "z": -5,
            "elements": [
                "modularmachinery:blockcasing@0"
            ]
        },
        {
            "x": -13,
            "y": 4,
            "z": -5,
            "elements": [
                "naturesaura:infused_stone@0"
            ]
        },
        {
            "x": 13,
            "y": -4,
            "z": 5,
            "elements": [
                "modularmachinery:blockcasing@0"
            ]
        },
        {
            "x": -14,
            "y": -3,
            "z": 5,
            "elements": [
                "modularmachinery:blockcasing@0"
            ]
        },
        {
            "x": 12,
            "y": 3,
            "z": -5,
            "elements": [
                "naturesaura:infused_stone@0"
            ]
        },
        {
            "x": 11,
            "y": 3,
            "z": -5,
            "elements": [
                "modularmachinery:blockcasing@0"
            ]
        },
        {
            "x": 10,
            "y": 3,
            "z": -5,
            "elements": [
                "modularmachinery:blockcasing@0"
            ]
        },
        {
            "x": 9,
            "y": 3,
            "z": -5,
            "elements": [
                "modularmachinery:blockcasing@0"
            ]
        },
        {
            "x": 8,
            "y": 3,
            "z": -5,
            "elements": [
                "modularmachinery:blockcasing@0"
            ]
        },
        {
            "x": 7,
            "y": 3,
            "z": -5,
            "elements": [
                "modularmachinery:blockcasing@0"
            ]
        },
        {
            "x": 6,
            "y": 3,
            "z": -5,
            "elements": [
                "modularmachinery:blockcasing@0"
            ]
        },
        {
            "x": 5,
            "y": 3,
            "z": -5,
            "elements": [
                "modularmachinery:blockcasing@0"
            ]
        },
        {
            "x": 4,
            "y": 3,
            "z": -5,
            "elements": [
                "naturesaura:infused_stone@0"
            ]
        },
        {
            "x": -4,
            "y": -3,
            "z": 5,
            "elements": [
                "modularmachinery:blockcasing@0"
            ]
        },
        {
            "x": 3,
            "y": -3,
            "z": 5,
            "elements": [
                "modularmachinery:blockcasing@0"
            ]
        },
        {
            "x": -5,
            "y": 3,
            "z": -5,
            "elements": [
                "naturesaura:infused_stone@0"
            ]
        },
        {
            "x": -6,
            "y": 3,
            "z": -5,
            "elements": [
                "modularmachinery:blockcasing@0"
            ]
        },
        {
            "x": -7,
            "y": 3,
            "z": -5,
            "elements": [
                "modularmachinery:blockcasing@0"
            ]
        },
        {
            "x": -8,
            "y": 3,
            "z": -5,
            "elements": [
                "modularmachinery:blockcasing@0"
            ]
        },
        {
            "x": -9,
            "y": 3,
            "z": -5,
            "elements": [
                "modularmachinery:blockcasing@0"
            ]
        },
        {
            "x": -10,
            "y": 3,
            "z": -5,
            "elements": [
                "modularmachinery:blockcasing@0"
            ]
        },
        {
            "x": -11,
            "y": 3,
            "z": -5,
            "elements": [
                "modularmachinery:blockcasing@0"
            ]
        },
        {
            "x": -12,
            "y": 3,
            "z": -5,
            "elements": [
                "modularmachinery:blockcasing@0"
            ]
        },
        {
            "x": -13,
            "y": 3,
            "z": -5,
            "elements": [
                "naturesaura:infused_stone@0"
            ]
        },
        {
            "x": 13,
            "y": -3,
            "z": 5,
            "elements": [
                "modularmachinery:blockcasing@0"
            ]
        },
        {
            "x": -14,
            "y": -2,
            "z": 5,
            "elements": [
                "modularmachinery:blockcasing@0"
            ]
        },
        {
            "x": 12,
            "y": 2,
            "z": -5,
            "elements": [
                "naturesaura:infused_stone@0"
            ]
        },
        {
            "x": 11,
            "y": 2,
            "z": -5,
            "elements": [
                "modularmachinery:blockcasing@0"
            ]
        },
        {
            "x": 10,
            "y": 2,
            "z": -5,
            "elements": [
                "modularmachinery:blockcasing@0"
            ]
        },
        {
            "x": 9,
            "y": 2,
            "z": -5,
            "elements": [
                "huajiage:huaji_star_block_sky@0"
            ]
        },
        {
            "x": 8,
            "y": 2,
            "z": -5,
            "elements": [
                "huajiage:huaji_star_block_sky@0"
            ]
        },
        {
            "x": 7,
            "y": 2,
            "z": -5,
            "elements": [
                "huajiage:huaji_star_block_sky@0"
            ]
        },
        {
            "x": 6,
            "y": 2,
            "z": -5,
            "elements": [
                "modularmachinery:blockcasing@0"
            ]
        },
        {
            "x": 5,
            "y": 2,
            "z": -5,
            "elements": [
                "modularmachinery:blockcasing@0"
            ]
        },
        {
            "x": 4,
            "y": 2,
            "z": -5,
            "elements": [
                "naturesaura:infused_stone@0"
            ]
        },
        {
            "x": -4,
            "y": -2,
            "z": 5,
            "elements": [
                "modularmachinery:blockcasing@0"
            ]
        },
        {
            "x": 3,
            "y": -2,
            "z": 5,
            "elements": [
                "modularmachinery:blockcasing@0"
            ]
        },
        {
            "x": -5,
            "y": 2,
            "z": -5,
            "elements": [
                "naturesaura:infused_stone@0"
            ]
        },
        {
            "x": -6,
            "y": 2,
            "z": -5,
            "elements": [
                "modularmachinery:blockcasing@0"
            ]
        },
        {
            "x": -7,
            "y": 2,
            "z": -5,
            "elements": [
                "modularmachinery:blockcasing@0"
            ]
        },
        {
            "x": -8,
            "y": 2,
            "z": -5,
            "elements": [
                "huajiage:huaji_star_block_sky@0"
            ]
        },
        {
            "x": -9,
            "y": 2,
            "z": -5,
            "elements": [
                "huajiage:huaji_star_block_sky@0"
            ]
        },
        {
            "x": -10,
            "y": 2,
            "z": -5,
            "elements": [
                "huajiage:huaji_star_block_sky@0"
            ]
        },
        {
            "x": -11,
            "y": 2,
            "z": -5,
            "elements": [
                "modularmachinery:blockcasing@0"
            ]
        },
        {
            "x": -12,
            "y": 2,
            "z": -5,
            "elements": [
                "modularmachinery:blockcasing@0"
            ]
        },
        {
            "x": -13,
            "y": 2,
            "z": -5,
            "elements": [
                "naturesaura:infused_stone@0"
            ]
        },
        {
            "x": 13,
            "y": -2,
            "z": 5,
            "elements": [
                "modularmachinery:blockcasing@0"
            ]
        },
        {
            "x": -14,
            "y": -1,
            "z": 5,
            "elements": [
                "modularmachinery:blockcasing@0"
            ]
        },
        {
            "x": 12,
            "y": 1,
            "z": -5,
            "elements": [
                "naturesaura:infused_stone@0"
            ]
        },
        {
            "x": 11,
            "y": 1,
            "z": -5,
            "elements": [
                "modularmachinery:blockcasing@0"
            ]
        },
        {
            "x": 10,
            "y": 1,
            "z": -5,
            "elements": [
                "modularmachinery:blockcasing@0"
            ]
        },
        {
            "x": 9,
            "y": 1,
            "z": -5,
            "elements": [
                "huajiage:huaji_star_block_sky@0"
            ]
        },
        {
            "x": 8,
            "y": 1,
            "z": -5,
            "elements": [
                "huajiage:huaji_star_block_sky@0"
            ]
        },
        {
            "x": 11,
            "y": 9,
            "z": -1,
            "elements": [
                "minecraft:purpur_block@0"
            ]
        },
        {
            "x": 7,
            "y": 1,
            "z": -5,
            "elements": [
                "huajiage:huaji_star_block_sky@0"
            ]
        },
        {
            "x": 10,
            "y": 9,
            "z": -1,
            "elements": [
                "minecraft:purpur_block@0"
            ]
        },
        {
            "x": 6,
            "y": 1,
            "z": -5,
            "elements": [
                "modularmachinery:blockcasing@0"
            ]
        },
        {
            "x": 9,
            "y": 9,
            "z": -1,
            "elements": [
                "minecraft:purpur_block@0"
            ]
        },
        {
            "x": 5,
            "y": 1,
            "z": -5,
            "elements": [
                "modularmachinery:blockcasing@0"
            ]
        },
        {
            "x": 8,
            "y": 9,
            "z": -1,
            "elements": [
                "minecraft:purpur_block@0"
            ]
        },
        {
            "x": 4,
            "y": 1,
            "z": -5,
            "elements": [
                "naturesaura:infused_stone@0"
            ]
        },
        {
            "x": 7,
            "y": 9,
            "z": -1,
            "elements": [
                "minecraft:purpur_block@0"
            ]
        },
        {
            "x": -4,
            "y": -1,
            "z": 5,
            "elements": [
                "modularmachinery:blockcasing@0"
            ]
        },
        {
            "x": 6,
            "y": 9,
            "z": -1,
            "elements": [
                "minecraft:purpur_block@0"
            ]
        },
        {
            "x": 5,
            "y": 9,
            "z": -1,
            "elements": [
                "minecraft:purpur_block@0"
            ]
        },
        {
            "x": 3,
            "y": -1,
            "z": 5,
            "elements": [
                "modularmachinery:blockcasing@0"
            ]
        },
        {
            "x": -5,
            "y": 1,
            "z": -5,
            "elements": [
                "naturesaura:infused_stone@0"
            ]
        },
        {
            "x": -6,
            "y": 1,
            "z": -5,
            "elements": [
                "modularmachinery:blockcasing@0"
            ]
        },
        {
            "x": -7,
            "y": 1,
            "z": -5,
            "elements": [
                "modularmachinery:blockcasing@0"
            ]
        },
        {
            "x": -8,
            "y": 1,
            "z": -5,
            "elements": [
                "huajiage:huaji_star_block_sky@0"
            ]
        },
        {
            "x": -9,
            "y": 1,
            "z": -5,
            "elements": [
                "huajiage:huaji_star_block_sky@0"
            ]
        },
        {
            "x": -10,
            "y": 1,
            "z": -5,
            "elements": [
                "huajiage:huaji_star_block_sky@0"
            ]
        },
        {
            "x": -6,
            "y": 9,
            "z": -1,
            "elements": [
                "minecraft:purpur_block@0"
            ]
        },
        {
            "x": -11,
            "y": 1,
            "z": -5,
            "elements": [
                "modularmachinery:blockcasing@0"
            ]
        },
        {
            "x": -7,
            "y": 9,
            "z": -1,
            "elements": [
                "minecraft:purpur_block@0"
            ]
        },
        {
            "x": -12,
            "y": 1,
            "z": -5,
            "elements": [
                "modularmachinery:blockcasing@0"
            ]
        },
        {
            "x": -8,
            "y": 9,
            "z": -1,
            "elements": [
                "minecraft:purpur_block@0"
            ]
        },
        {
            "x": -13,
            "y": 1,
            "z": -5,
            "elements": [
                "naturesaura:infused_stone@0"
            ]
        },
        {
            "x": -9,
            "y": 9,
            "z": -1,
            "elements": [
                "minecraft:purpur_block@0"
            ]
        },
        {
            "x": 13,
            "y": -1,
            "z": 5,
            "elements": [
                "modularmachinery:blockcasing@0"
            ]
        },
        {
            "x": -10,
            "y": 9,
            "z": -1,
            "elements": [
                "minecraft:purpur_block@0"
            ]
        },
        {
            "x": -11,
            "y": 9,
            "z": -1,
            "elements": [
                "minecraft:purpur_block@0"
            ]
        },
        {
            "x": -12,
            "y": 9,
            "z": -1,
            "elements": [
                "minecraft:purpur_block@0"
            ]
        },
        {
            "x": -14,
            "y": 0,
            "z": 5,
            "elements": [
                "modularmachinery:blockcasing@0"
            ]
        },
        {
            "x": 12,
            "y": 0,
            "z": -5,
            "elements": [
                "naturesaura:infused_stone@0"
            ]
        },
        {
            "x": 11,
            "y": 0,
            "z": -5,
            "elements": [
                "modularmachinery:blockcasing@0"
            ]
        },
        {
            "x": 10,
            "y": 0,
            "z": -5,
            "elements": [
                "modularmachinery:blockcasing@0"
            ]
        },
        {
            "x": 9,
            "y": 0,
            "z": -5,
            "elements": [
                "huajiage:huaji_star_block_sky@0"
            ]
        },
        {
            "x": 12,
            "y": 8,
            "z": -1,
            "elements": [
                "bloodmagic:demon_extras@0"
            ]
        },
        {
            "x": 8,
            "y": 0,
            "z": -5,
            "elements": [
                "huajiage:huaji_star_block_sky@0"
            ]
        },
        {
            "x": 7,
            "y": 0,
            "z": -5,
            "elements": [
                "huajiage:huaji_star_block_sky@0"
            ]
        },
        {
            "x": 6,
            "y": 0,
            "z": -5,
            "elements": [
                "modularmachinery:blockcasing@0"
            ]
        },
        {
            "x": -11,
            "y": -8,
            "z": 1,
            "elements": [
                "minecraft:purpur_block@0"
            ]
        },
        {
            "x": 5,
            "y": 0,
            "z": -5,
            "elements": [
                "modularmachinery:blockcasing@0"
            ]
        },
        {
            "x": -10,
            "y": -8,
            "z": 1,
            "elements": [
                "minecraft:purpur_block@0"
            ]
        },
        {
            "x": -9,
            "y": -8,
            "z": 1,
            "elements": [
                "minecraft:purpur_block@0"
            ]
        },
        {
            "x": 4,
            "y": 0,
            "z": -5,
            "elements": [
                "naturesaura:infused_stone@0"
            ]
        },
        {
            "x": -8,
            "y": -8,
            "z": 1,
            "elements": [
                "minecraft:purpur_block@0"
            ]
        },
        {
            "x": -4,
            "y": 0,
            "z": 5,
            "elements": [
                "modularmachinery:blockcasing@0"
            ]
        },
        {
            "x": -7,
            "y": -8,
            "z": 1,
            "elements": [
                "minecraft:purpur_block@0"
            ]
        },
        {
            "x": 4,
            "y": 8,
            "z": -1,
            "elements": [
                "bloodmagic:demon_extras@0"
            ]
        },
        {
            "x": 3,
            "y": 0,
            "z": 5,
            "elements": [
                "modularmachinery:blockcasing@0"
            ]
        },
        {
            "x": -5,
            "y": 0,
            "z": -5,
            "elements": [
                "naturesaura:infused_stone@0"
            ]
        },
        {
            "x": -6,
            "y": 0,
            "z": -5,
            "elements": [
                "modularmachinery:blockcasing@0"
            ]
        },
        {
            "x": -7,
            "y": 0,
            "z": -5,
            "elements": [
                "modularmachinery:blockcasing@0"
            ]
        },
        {
            "x": -8,
            "y": 0,
            "z": -5,
            "elements": [
                "huajiage:huaji_star_block_sky@0"
            ]
        },
        {
            "x": -9,
            "y": 0,
            "z": -5,
            "elements": [
                "huajiage:huaji_star_block_sky@0"
            ]
        },
        {
            "x": -5,
            "y": 8,
            "z": -1,
            "elements": [
                "bloodmagic:demon_extras@0"
            ]
        },
        {
            "x": -10,
            "y": 0,
            "z": -5,
            "elements": [
                "huajiage:huaji_star_block_sky@0"
            ]
        },
        {
            "x": 6,
            "y": -8,
            "z": 1,
            "elements": [
                "minecraft:purpur_block@0"
            ]
        },
        {
            "x": -11,
            "y": 0,
            "z": -5,
            "elements": [
                "modularmachinery:blockcasing@0"
            ]
        },
        {
            "x": 7,
            "y": -8,
            "z": 1,
            "elements": [
                "minecraft:purpur_block@0"
            ]
        },
        {
            "x": -12,
            "y": 0,
            "z": -5,
            "elements": [
                "modularmachinery:blockcasing@0"
            ]
        },
        {
            "x": -13,
            "y": 0,
            "z": -5,
            "elements": [
                "naturesaura:infused_stone@0"
            ]
        },
        {
            "x": 8,
            "y": -8,
            "z": 1,
            "elements": [
                "minecraft:purpur_block@0"
            ]
        },
        {
            "x": 13,
            "y": 0,
            "z": 5,
            "elements": [
                "modularmachinery:blockcasing@0"
            ]
        },
        {
            "x": 9,
            "y": -8,
            "z": 1,
            "elements": [
                "minecraft:purpur_block@0"
            ]
        },
        {
            "x": 10,
            "y": -8,
            "z": 1,
            "elements": [
                "minecraft:purpur_block@0"
            ]
        },
        {
            "x": -13,
            "y": 8,
            "z": -1,
            "elements": [
                "bloodmagic:demon_extras@0"
            ]
        },
        {
            "x": -14,
            "y": 1,
            "z": 5,
            "elements": [
                "modularmachinery:blockcasing@0"
            ]
        },
        {
            "x": 12,
            "y": -1,
            "z": -5,
            "elements": [
                "naturesaura:infused_stone@0"
            ]
        },
        {
            "x": 11,
            "y": -1,
            "z": -5,
            "elements": [
                "modularmachinery:blockcasing@0"
            ]
        },
        {
            "x": 10,
            "y": -1,
            "z": -5,
            "elements": [
                "modularmachinery:blockcasing@0"
            ]
        },
        {
            "x": 13,
            "y": 7,
            "z": -1,
            "elements": [
                "bloodmagic:demon_extras@1"
            ]
        },
        {
            "x": 9,
            "y": -1,
            "z": -5,
            "elements": [
                "modularmachinery:blockcasing@0"
            ]
        },
        {
            "x": 8,
            "y": -1,
            "z": -5,
            "elements": [
                "modularmachinery:blockcasing@0"
            ]
        },
        {
            "x": 7,
            "y": -1,
            "z": -5,
            "elements": [
                "modularmachinery:blockcasing@0"
            ]
        },
        {
            "x": -12,
            "y": -7,
            "z": 1,
            "elements": [
                "bloodmagic:demon_extras@0"
            ]
        },
        {
            "x": 6,
            "y": -1,
            "z": -5,
            "elements": [
                "modularmachinery:blockcasing@0"
            ]
        },
        {
            "x": 5,
            "y": -1,
            "z": -5,
            "elements": [
                "modularmachinery:blockcasing@0"
            ]
        },
        {
            "x": -9,
            "y": -7,
            "z": 1,
            "elements": [
                "minecraft:sea_lantern@0"
            ]
        },
        {
            "x": 4,
            "y": -1,
            "z": -5,
            "elements": [
                "naturesaura:infused_stone@0"
            ]
        },
        {
            "x": -4,
            "y": 1,
            "z": 5,
            "elements": [
                "modularmachinery:blockcasing@0"
            ]
        },
        {
            "x": -6,
            "y": -7,
            "z": 1,
            "elements": [
                "bloodmagic:demon_extras@0"
            ]
        },
        {
            "x": 3,
            "y": 7,
            "z": -1,
            "elements": [
                "bloodmagic:demon_extras@1"
            ]
        },
        {
            "x": 3,
            "y": 1,
            "z": 5,
            "elements": [
                "modularmachinery:blockcasing@0"
            ]
        },
        {
            "x": -5,
            "y": -1,
            "z": -5,
            "elements": [
                "naturesaura:infused_stone@0"
            ]
        },
        {
            "x": -6,
            "y": -1,
            "z": -5,
            "elements": [
                "modularmachinery:blockcasing@0"
            ]
        },
        {
            "x": -7,
            "y": -1,
            "z": -5,
            "elements": [
                "modularmachinery:blockcasing@0"
            ]
        },
        {
            "x": -8,
            "y": -1,
            "z": -5,
            "elements": [
                "modularmachinery:blockcasing@0"
            ]
        },
        {
            "x": -4,
            "y": 7,
            "z": -1,
            "elements": [
                "bloodmagic:demon_extras@1"
            ]
        },
        {
            "x": -9,
            "y": -1,
            "z": -5,
            "elements": [
                "modularmachinery:blockcasing@0"
            ]
        },
        {
            "x": 5,
            "y": -7,
            "z": 1,
            "elements": [
                "bloodmagic:demon_extras@0"
            ]
        },
        {
            "x": -10,
            "y": -1,
            "z": -5,
            "elements": [
                "modularmachinery:blockcasing@0"
            ]
        },
        {
            "x": -11,
            "y": -1,
            "z": -5,
            "elements": [
                "modularmachinery:blockcasing@0"
            ]
        },
        {
            "x": -12,
            "y": -1,
            "z": -5,
            "elements": [
                "modularmachinery:blockcasing@0"
            ]
        },
        {
            "x": -13,
            "y": -1,
            "z": -5,
            "elements": [
                "naturesaura:infused_stone@0"
            ]
        },
        {
            "x": 8,
            "y": -7,
            "z": 1,
            "elements": [
                "minecraft:sea_lantern@0"
            ]
        },
        {
            "x": 13,
            "y": 1,
            "z": 5,
            "elements": [
                "modularmachinery:blockcasing@0"
            ]
        },
        {
            "x": 11,
            "y": -7,
            "z": 1,
            "elements": [
                "bloodmagic:demon_extras@0"
            ]
        },
        {
            "x": -14,
            "y": 7,
            "z": -1,
            "elements": [
                "bloodmagic:demon_extras@1"
            ]
        },
        {
            "x": -14,
            "y": 2,
            "z": 5,
            "elements": [
                "modularmachinery:blockcasing@0"
            ]
        },
        {
            "x": 12,
            "y": -2,
            "z": -5,
            "elements": [
                "naturesaura:infused_stone@0"
            ]
        },
        {
            "x": 11,
            "y": -2,
            "z": -5,
            "elements": [
                "modularmachinery:blockcasing@0"
            ]
        },
        {
            "x": 10,
            "y": -2,
            "z": -5,
            "elements": [
                "modularmachinery:blockcasing@0"
            ]
        },
        {
            "x": 13,
            "y": 6,
            "z": -1,
            "elements": [
                "astralsorcery:blockmarble@6"
            ]
        },
        {
            "x": 9,
            "y": -2,
            "z": -5,
            "elements": [
                "modularmachinery:blockcasing@0"
            ]
        },
        {
            "x": -13,
            "y": -6,
            "z": 1,
            "elements": [
                "bloodmagic:demon_extras@1"
            ]
        },
        {
            "x": 8,
            "y": -2,
            "z": -5,
            "elements": [
                "modularmachinery:blockcasing@0"
            ]
        },
        {
            "x": 7,
            "y": -2,
            "z": -5,
            "elements": [
                "modularmachinery:blockcasing@0"
            ]
        },
        {
            "x": 6,
            "y": -2,
            "z": -5,
            "elements": [
                "modularmachinery:blockcasing@0"
            ]
        },
        {
            "x": 5,
            "y": -2,
            "z": -5,
            "elements": [
                "modularmachinery:blockcasing@0"
            ]
        },
        {
            "x": 4,
            "y": -2,
            "z": -5,
            "elements": [
                "naturesaura:infused_stone@0"
            ]
        },
        {
            "x": -4,
            "y": 2,
            "z": 5,
            "elements": [
                "modularmachinery:blockcasing@0"
            ]
        },
        {
            "x": -5,
            "y": -6,
            "z": 1,
            "elements": [
                "bloodmagic:demon_extras@1"
            ]
        },
        {
            "x": 3,
            "y": 6,
            "z": -1,
            "elements": [
                "astralsorcery:blockmarble@6"
            ]
        },
        {
            "x": 3,
            "y": 2,
            "z": 5,
            "elements": [
                "modularmachinery:blockcasing@0"
            ]
        },
        {
            "x": -5,
            "y": -2,
            "z": -5,
            "elements": [
                "naturesaura:infused_stone@0"
            ]
        },
        {
            "x": -6,
            "y": -2,
            "z": -5,
            "elements": [
                "modularmachinery:blockcasing@0"
            ]
        },
        {
            "x": -7,
            "y": -2,
            "z": -5,
            "elements": [
                "modularmachinery:blockcasing@0"
            ]
        },
        {
            "x": -8,
            "y": -2,
            "z": -5,
            "elements": [
                "modularmachinery:blockcasing@0"
            ]
        },
        {
            "x": -4,
            "y": 6,
            "z": -1,
            "elements": [
                "astralsorcery:blockmarble@6"
            ]
        },
        {
            "x": -9,
            "y": -2,
            "z": -5,
            "elements": [
                "modularmachinery:blockcasing@0"
            ]
        },
        {
            "x": 4,
            "y": -6,
            "z": 1,
            "elements": [
                "bloodmagic:demon_extras@1"
            ]
        },
        {
            "x": -10,
            "y": -2,
            "z": -5,
            "elements": [
                "modularmachinery:blockcasing@0"
            ]
        },
        {
            "x": -11,
            "y": -2,
            "z": -5,
            "elements": [
                "modularmachinery:blockcasing@0"
            ]
        },
        {
            "x": -12,
            "y": -2,
            "z": -5,
            "elements": [
                "modularmachinery:blockcasing@0"
            ]
        },
        {
            "x": -13,
            "y": -2,
            "z": -5,
            "elements": [
                "naturesaura:infused_stone@0"
            ]
        },
        {
            "x": 13,
            "y": 2,
            "z": 5,
            "elements": [
                "modularmachinery:blockcasing@0"
            ]
        },
        {
            "x": 12,
            "y": -6,
            "z": 1,
            "elements": [
                "bloodmagic:demon_extras@1"
            ]
        },
        {
            "x": -14,
            "y": 6,
            "z": -1,
            "elements": [
                "astralsorcery:blockmarble@6"
            ]
        },
        {
            "x": -14,
            "y": 3,
            "z": 5,
            "elements": [
                "modularmachinery:blockcasing@0"
            ]
        },
        {
            "x": 12,
            "y": -3,
            "z": -5,
            "elements": [
                "naturesaura:infused_stone@0"
            ]
        },
        {
            "x": 11,
            "y": -3,
            "z": -5,
            "elements": [
                "modularmachinery:blockcasing@0"
            ]
        },
        {
            "x": 10,
            "y": -3,
            "z": -5,
            "elements": [
                "modularmachinery:blockcasing@0"
            ]
        },
        {
            "x": 13,
            "y": 5,
            "z": -1,
            "elements": [
                "modularmachinery:blockcasing@0"
            ]
        },
        {
            "x": 9,
            "y": -3,
            "z": -5,
            "elements": [
                "modularmachinery:blockcasing@0"
            ]
        },
        {
            "x": -14,
            "y": -5,
            "z": 1,
            "elements": [
                "astralsorcery:blockmarble@6"
            ]
        },
        {
            "x": 8,
            "y": -3,
            "z": -5,
            "elements": [
                "modularmachinery:blockcasing@0"
            ]
        },
        {
            "x": 7,
            "y": -3,
            "z": -5,
            "elements": [
                "modularmachinery:blockcasing@0"
            ]
        },
        {
            "x": 6,
            "y": -3,
            "z": -5,
            "elements": [
                "modularmachinery:blockcasing@0"
            ]
        },
        {
            "x": 5,
            "y": -3,
            "z": -5,
            "elements": [
                "modularmachinery:blockcasing@0"
            ]
        },
        {
            "x": 4,
            "y": -3,
            "z": -5,
            "elements": [
                "naturesaura:infused_stone@0"
            ]
        },
        {
            "x": -4,
            "y": 3,
            "z": 5,
            "elements": [
                "modularmachinery:blockcasing@0"
            ]
        },
        {
            "x": 3,
            "y": 5,
            "z": -1,
            "elements": [
                "modularmachinery:blockcasing@0"
            ]
        },
        {
            "x": -4,
            "y": -5,
            "z": 1,
            "elements": [
                "astralsorcery:blockmarble@6"
            ]
        },
        {
            "x": 3,
            "y": 3,
            "z": 5,
            "elements": [
                "modularmachinery:blockcasing@0"
            ]
        },
        {
            "x": -5,
            "y": -3,
            "z": -5,
            "elements": [
                "naturesaura:infused_stone@0"
            ]
        },
        {
            "x": -6,
            "y": -3,
            "z": -5,
            "elements": [
                "modularmachinery:blockcasing@0"
            ]
        },
        {
            "x": -7,
            "y": -3,
            "z": -5,
            "elements": [
                "modularmachinery:blockcasing@0"
            ]
        },
        {
            "x": 3,
            "y": -5,
            "z": 1,
            "elements": [
                "astralsorcery:blockmarble@6"
            ]
        },
        {
            "x": -8,
            "y": -3,
            "z": -5,
            "elements": [
                "modularmachinery:blockcasing@0"
            ]
        },
        {
            "x": -4,
            "y": 5,
            "z": -1,
            "elements": [
                "modularmachinery:blockcasing@0"
            ]
        },
        {
            "x": -9,
            "y": -3,
            "z": -5,
            "elements": [
                "modularmachinery:blockcasing@0"
            ]
        },
        {
            "x": -10,
            "y": -3,
            "z": -5,
            "elements": [
                "modularmachinery:blockcasing@0"
            ]
        },
        {
            "x": -11,
            "y": -3,
            "z": -5,
            "elements": [
                "modularmachinery:blockcasing@0"
            ]
        },
        {
            "x": -12,
            "y": -3,
            "z": -5,
            "elements": [
                "modularmachinery:blockcasing@0"
            ]
        },
        {
            "x": -13,
            "y": -3,
            "z": -5,
            "elements": [
                "naturesaura:infused_stone@0"
            ]
        },
        {
            "x": 13,
            "y": 3,
            "z": 5,
            "elements": [
                "modularmachinery:blockcasing@0"
            ]
        },
        {
            "x": 13,
            "y": -5,
            "z": 1,
            "elements": [
                "astralsorcery:blockmarble@6"
            ]
        },
        {
            "x": -14,
            "y": 5,
            "z": -1,
            "elements": [
                "modularmachinery:blockcasing@0"
            ]
        },
        {
            "x": -14,
            "y": 4,
            "z": 5,
            "elements": [
                "modularmachinery:blockcasing@0"
            ]
        },
        {
            "x": 12,
            "y": -4,
            "z": -5,
            "elements": [
                "naturesaura:infused_stone@0"
            ]
        },
        {
            "x": 11,
            "y": -4,
            "z": -5,
            "elements": [
                "modularmachinery:blockcasing@0"
            ]
        },
        {
            "x": 10,
            "y": -4,
            "z": -5,
            "elements": [
                "modularmachinery:blockcasing@0"
            ]
        },
        {
            "x": 13,
            "y": 4,
            "z": -1,
            "elements": [
                "modularmachinery:blockcasing@0"
            ]
        },
        {
            "x": 9,
            "y": -4,
            "z": -5,
            "elements": [
                "modularmachinery:blockcasing@0"
            ]
        },
        {
            "x": -14,
            "y": -4,
            "z": 1,
            "elements": [
                "modularmachinery:blockcasing@0"
            ]
        },
        {
            "x": 8,
            "y": -4,
            "z": -5,
            "elements": [
                "modularmachinery:blockcasing@0"
            ]
        },
        {
            "x": 7,
            "y": -4,
            "z": -5,
            "elements": [
                "modularmachinery:blockcasing@0"
            ]
        },
        {
            "x": 6,
            "y": -4,
            "z": -5,
            "elements": [
                "modularmachinery:blockcasing@0"
            ]
        },
        {
            "x": 5,
            "y": -4,
            "z": -5,
            "elements": [
                "modularmachinery:blockcasing@0"
            ]
        },
        {
            "x": 4,
            "y": -4,
            "z": -5,
            "elements": [
                "naturesaura:infused_stone@0"
            ]
        },
        {
            "x": -4,
            "y": 4,
            "z": 5,
            "elements": [
                "modularmachinery:blockcasing@0"
            ]
        },
        {
            "x": 3,
            "y": 4,
            "z": -1,
            "elements": [
                "modularmachinery:blockcasing@0"
            ]
        },
        {
            "x": -4,
            "y": -4,
            "z": 1,
            "elements": [
                "modularmachinery:blockcasing@0"
            ]
        },
        {
            "x": 3,
            "y": 4,
            "z": 5,
            "elements": [
                "modularmachinery:blockcasing@0"
            ]
        },
        {
            "x": -5,
            "y": -4,
            "z": -5,
            "elements": [
                "naturesaura:infused_stone@0"
            ]
        },
        {
            "x": -6,
            "y": -4,
            "z": -5,
            "elements": [
                "modularmachinery:blockcasing@0"
            ]
        },
        {
            "x": -7,
            "y": -4,
            "z": -5,
            "elements": [
                "modularmachinery:blockcasing@0"
            ]
        },
        {
            "x": 3,
            "y": -4,
            "z": 1,
            "elements": [
                "modularmachinery:blockcasing@0"
            ]
        },
        {
            "x": -8,
            "y": -4,
            "z": -5,
            "elements": [
                "modularmachinery:blockcasing@0"
            ]
        },
        {
            "x": -4,
            "y": 4,
            "z": -1,
            "elements": [
                "modularmachinery:blockcasing@0"
            ]
        },
        {
            "x": -9,
            "y": -4,
            "z": -5,
            "elements": [
                "modularmachinery:blockcasing@0"
            ]
        },
        {
            "x": -10,
            "y": -4,
            "z": -5,
            "elements": [
                "modularmachinery:blockcasing@0"
            ]
        },
        {
            "x": -11,
            "y": -4,
            "z": -5,
            "elements": [
                "modularmachinery:blockcasing@0"
            ]
        },
        {
            "x": -12,
            "y": -4,
            "z": -5,
            "elements": [
                "modularmachinery:blockcasing@0"
            ]
        },
        {
            "x": -13,
            "y": -4,
            "z": -5,
            "elements": [
                "naturesaura:infused_stone@0"
            ]
        },
        {
            "x": 13,
            "y": 4,
            "z": 5,
            "elements": [
                "modularmachinery:blockcasing@0"
            ]
        },
        {
            "x": 13,
            "y": -4,
            "z": 1,
            "elements": [
                "modularmachinery:blockcasing@0"
            ]
        },
        {
            "x": -14,
            "y": 5,
            "z": 5,
            "elements": [
                "modularmachinery:blockcasing@0"
            ]
        },
        {
            "x": -14,
            "y": 4,
            "z": -1,
            "elements": [
                "modularmachinery:blockcasing@0"
            ]
        },
        {
            "x": 12,
            "y": -5,
            "z": -5,
            "elements": [
                "bloodarsenal:blood_infused_iron_block@0"
            ]
        },
        {
            "x": 11,
            "y": -5,
            "z": -5,
            "elements": [
                "astralsorcery:blockmarble@6"
            ]
        },
        {
            "x": 10,
            "y": -5,
            "z": -5,
            "elements": [
                "astralsorcery:blockmarble@6"
            ]
        },
        {
            "x": 13,
            "y": 3,
            "z": -1,
            "elements": [
                "modularmachinery:blockcasing@0"
            ]
        },
        {
            "x": 9,
            "y": -5,
            "z": -5,
            "elements": [
                "astralsorcery:blockmarble@6"
            ]
        },
        {
            "x": -14,
            "y": -3,
            "z": 1,
            "elements": [
                "modularmachinery:blockcasing@0"
            ]
        },
        {
            "x": 8,
            "y": -5,
            "z": -5,
            "elements": [
                "astralsorcery:blockmarble@6"
            ]
        },
        {
            "x": 7,
            "y": -5,
            "z": -5,
            "elements": [
                "astralsorcery:blockmarble@6"
            ]
        },
        {
            "x": 6,
            "y": -5,
            "z": -5,
            "elements": [
                "astralsorcery:blockmarble@6"
            ]
        },
        {
            "x": 5,
            "y": -5,
            "z": -5,
            "elements": [
                "astralsorcery:blockmarble@6"
            ]
        },
        {
            "x": 4,
            "y": -5,
            "z": -5,
            "elements": [
                "bloodarsenal:blood_infused_iron_block@0"
            ]
        },
        {
            "x": -4,
            "y": 5,
            "z": 5,
            "elements": [
                "modularmachinery:blockcasing@0"
            ]
        },
        {
            "x": 3,
            "y": 3,
            "z": -1,
            "elements": [
                "minecraft:end_stone@0"
            ]
        },
        {
            "x": -4,
            "y": -3,
            "z": 1,
            "elements": [
                "modularmachinery:blockcasing@0"
            ]
        },
        {
            "x": 3,
            "y": 5,
            "z": 5,
            "elements": [
                "modularmachinery:blockcasing@0"
            ]
        },
        {
            "x": -5,
            "y": -5,
            "z": -5,
            "elements": [
                "bloodarsenal:blood_infused_iron_block@0"
            ]
        },
        {
            "x": -6,
            "y": -5,
            "z": -5,
            "elements": [
                "astralsorcery:blockmarble@6"
            ]
        },
        {
            "x": -7,
            "y": -5,
            "z": -5,
            "elements": [
                "astralsorcery:blockmarble@6"
            ]
        },
        {
            "x": 3,
            "y": -3,
            "z": 1,
            "elements": [
                "modularmachinery:blockcasing@0"
            ]
        },
        {
            "x": -8,
            "y": -5,
            "z": -5,
            "elements": [
                "astralsorcery:blockmarble@6"
            ]
        },
        {
            "x": -4,
            "y": 3,
            "z": -1,
            "elements": [
                "minecraft:end_stone@0"
            ]
        },
        {
            "x": -9,
            "y": -5,
            "z": -5,
            "elements": [
                "astralsorcery:blockmarble@6"
            ]
        },
        {
            "x": -10,
            "y": -5,
            "z": -5,
            "elements": [
                "astralsorcery:blockmarble@6"
            ]
        },
        {
            "x": -11,
            "y": -5,
            "z": -5,
            "elements": [
                "astralsorcery:blockmarble@6"
            ]
        },
        {
            "x": -12,
            "y": -5,
            "z": -5,
            "elements": [
                "astralsorcery:blockmarble@6"
            ]
        },
        {
            "x": -13,
            "y": -5,
            "z": -5,
            "elements": [
                "bloodarsenal:blood_infused_iron_block@0"
            ]
        },
        {
            "x": 13,
            "y": 5,
            "z": 5,
            "elements": [
                "modularmachinery:blockcasing@0"
            ]
        },
        {
            "x": 13,
            "y": -3,
            "z": 1,
            "elements": [
                "modularmachinery:blockcasing@0"
            ]
        },
        {
            "x": -14,
            "y": 6,
            "z": 5,
            "elements": [
                "astralsorcery:blockmarble@6"
            ]
        },
        {
            "x": -14,
            "y": 3,
            "z": -1,
            "elements": [
                "modularmachinery:blockcasing@0"
            ]
        },
        {
            "x": 13,
            "y": 2,
            "z": -1,
            "elements": [
                "modularmachinery:blockcasing@0"
            ]
        },
        {
            "x": -14,
            "y": -2,
            "z": 1,
            "elements": [
                "modularmachinery:blockcasing@0"
            ]
        },
        {
            "x": -4,
            "y": 6,
            "z": 5,
            "elements": [
                "astralsorcery:blockmarble@6"
            ]
        },
        {
            "x": 3,
            "y": 2,
            "z": -1,
            "elements": [
                "minecraft:end_stone@0"
            ]
        },
        {
            "x": -4,
            "y": -2,
            "z": 1,
            "elements": [
                "modularmachinery:blockcasing@0"
            ]
        },
        {
            "x": 3,
            "y": 6,
            "z": 5,
            "elements": [
                "astralsorcery:blockmarble@6"
            ]
        },
        {
            "x": 3,
            "y": -2,
            "z": 1,
            "elements": [
                "modularmachinery:blockcasing@0"
            ]
        },
        {
            "x": -4,
            "y": 2,
            "z": -1,
            "elements": [
                "minecraft:end_stone@0"
            ]
        },
        {
            "x": 13,
            "y": 6,
            "z": 5,
            "elements": [
                "astralsorcery:blockmarble@6"
            ]
        },
        {
            "x": 13,
            "y": -2,
            "z": 1,
            "elements": [
                "modularmachinery:blockcasing@0"
            ]
        },
        {
            "x": -14,
            "y": 7,
            "z": 5,
            "elements": [
                "bloodmagic:demon_extras@1"
            ]
        },
        {
            "x": -14,
            "y": 2,
            "z": -1,
            "elements": [
                "modularmachinery:blockcasing@0"
            ]
        },
        {
            "x": 13,
            "y": 1,
            "z": -1,
            "elements": [
                "modularmachinery:blockcasing@0"
            ]
        },
        {
            "x": -14,
            "y": -1,
            "z": 1,
            "elements": [
                "modularmachinery:blockcasing@0"
            ]
        },
        {
            "x": -4,
            "y": 7,
            "z": 5,
            "elements": [
                "bloodmagic:demon_extras@1"
            ]
        },
        {
            "x": 3,
            "y": 1,
            "z": -1,
            "elements": [
                "minecraft:end_stone@0"
            ]
        },
        {
            "x": -4,
            "y": -1,
            "z": 1,
            "elements": [
                "minecraft:end_stone@0"
            ]
        },
        {
            "x": -3,
            "y": -1,
            "z": 1,
            "elements": [
                "minecraft:end_stone@0"
            ]
        },
        {
            "x": -2,
            "y": -1,
            "z": 1,
            "elements": [
                "minecraft:end_stone@0"
            ]
        },
        {
            "x": -1,
            "y": -1,
            "z": 1,
            "elements": [
                "minecraft:end_stone@0"
            ]
        },
        {
            "x": 3,
            "y": 7,
            "z": 5,
            "elements": [
                "bloodmagic:demon_extras@1"
            ]
        },
        {
            "x": 0,
            "y": -1,
            "z": 1,
            "elements": [
                "minecraft:end_stone@0"
            ]
        },
        {
            "x": 1,
            "y": -1,
            "z": 1,
            "elements": [
                "minecraft:end_stone@0"
            ]
        },
        {
            "x": 2,
            "y": -1,
            "z": 1,
            "elements": [
                "minecraft:end_stone@0"
            ]
        },
        {
            "x": 3,
            "y": -1,
            "z": 1,
            "elements": [
                "minecraft:end_stone@0"
            ]
        },
        {
            "x": -4,
            "y": 1,
            "z": -1,
            "elements": [
                "minecraft:end_stone@0"
            ]
        },
        {
            "x": 13,
            "y": 7,
            "z": 5,
            "elements": [
                "bloodmagic:demon_extras@1"
            ]
        },
        {
            "x": 13,
            "y": -1,
            "z": 1,
            "elements": [
                "modularmachinery:blockcasing@0"
            ]
        },
        {
            "x": -14,
            "y": 1,
            "z": -1,
            "elements": [
                "modularmachinery:blockcasing@0"
            ]
        },
        {
            "x": -13,
            "y": 8,
            "z": 5,
            "elements": [
                "bloodmagic:demon_extras@0"
            ]
        },
        {
            "x": -12,
            "y": 8,
            "z": 5,
            "elements": [
                "bloodmagic:demon_extras@0"
            ]
        },
        {
            "x": 13,
            "y": 0,
            "z": -1,
            "elements": [
                "modularmachinery:blockcasing@0"
            ]
        },
        {
            "x": -14,
            "y": 0,
            "z": 1,
            "elements": [
                "modularmachinery:blockcasing@0"
            ]
        },
        {
            "x": -6,
            "y": 8,
            "z": 5,
            "elements": [
                "bloodmagic:demon_extras@0"
            ]
        },
        {
            "x": -5,
            "y": 8,
            "z": 5,
            "elements": [
                "bloodmagic:demon_extras@0"
            ]
        },
        {
            "x": 3,
            "y": 0,
            "z": -1,
            "elements": [
                "minecraft:end_stone@0"
            ]
        },
        {
            "x": 4,
            "y": 8,
            "z": 5,
            "elements": [
                "bloodmagic:demon_extras@0"
            ]
        },
        {
            "x": 5,
            "y": 8,
            "z": 5,
            "elements": [
                "bloodmagic:demon_extras@0"
            ]
        },
        {
            "x": -4,
            "y": 0,
            "z": -1,
            "elements": [
                "minecraft:end_stone@0"
            ]
        },
        {
            "x": 11,
            "y": 8,
            "z": 5,
            "elements": [
                "bloodmagic:demon_extras@0"
            ]
        },
        {
            "x": 12,
            "y": 8,
            "z": 5,
            "elements": [
                "bloodmagic:demon_extras@0"
            ]
        },
        {
            "x": 13,
            "y": 0,
            "z": 1,
            "elements": [
                "modularmachinery:blockcasing@0"
            ]
        },
        {
            "x": -14,
            "y": 0,
            "z": -1,
            "elements": [
                "modularmachinery:blockcasing@0"
            ]
        },
        {
            "x": -11,
            "y": 9,
            "z": 5,
            "elements": [
                "minecraft:purpur_block@0"
            ]
        },
        {
            "x": 13,
            "y": -1,
            "z": -1,
            "elements": [
                "modularmachinery:blockcasing@0"
            ]
        },
        {
            "x": -14,
            "y": 1,
            "z": 1,
            "elements": [
                "modularmachinery:blockcasing@0"
            ]
        },
        {
            "x": -10,
            "y": 9,
            "z": 5,
            "elements": [
                "minecraft:purpur_block@0"
            ]
        },
        {
            "x": -9,
            "y": 9,
            "z": 5,
            "elements": [
                "minecraft:purpur_block@0"
            ]
        },
        {
            "x": -8,
            "y": 9,
            "z": 5,
            "elements": [
                "minecraft:purpur_block@0"
            ]
        },
        {
            "x": -7,
            "y": 9,
            "z": 5,
            "elements": [
                "minecraft:purpur_block@0"
            ]
        },
        {
            "x": 3,
            "y": -1,
            "z": -1,
            "elements": [
                "minecraft:end_stone@0"
            ]
        },
        {
            "x": 6,
            "y": 9,
            "z": 5,
            "elements": [
                "minecraft:purpur_block@0"
            ]
        },
        {
            "x": 7,
            "y": 9,
            "z": 5,
            "elements": [
                "minecraft:purpur_block@0"
            ]
        },
        {
            "x": -4,
            "y": -1,
            "z": -1,
            "elements": [
                "minecraft:end_stone@0"
            ]
        },
        {
            "x": 8,
            "y": 9,
            "z": 5,
            "elements": [
                "minecraft:purpur_block@0"
            ]
        },
        {
            "x": 9,
            "y": 9,
            "z": 5,
            "elements": [
                "minecraft:purpur_block@0"
            ]
        },
        {
            "x": 10,
            "y": 9,
            "z": 5,
            "elements": [
                "minecraft:purpur_block@0"
            ]
        },
        {
            "x": 13,
            "y": 1,
            "z": 1,
            "elements": [
                "modularmachinery:blockcasing@0"
            ]
        },
        {
            "x": -14,
            "y": -1,
            "z": -1,
            "elements": [
                "modularmachinery:blockcasing@0"
            ]
        },
        {
            "x": 13,
            "y": -2,
            "z": -1,
            "elements": [
                "modularmachinery:blockcasing@0"
            ]
        },
        {
            "x": -14,
            "y": 2,
            "z": 1,
            "elements": [
                "modularmachinery:blockcasing@0"
            ]
        },
        {
            "x": 3,
            "y": -2,
            "z": -1,
            "elements": [
                "modularmachinery:blockcasing@0"
            ]
        },
        {
            "x": -4,
            "y": -2,
            "z": -1,
            "elements": [
                "modularmachinery:blockcasing@0"
            ]
        },
        {
            "x": 13,
            "y": 2,
            "z": 1,
            "elements": [
                "modularmachinery:blockcasing@0"
            ]
        },
        {
            "x": -14,
            "y": -2,
            "z": -1,
            "elements": [
                "modularmachinery:blockcasing@0"
            ]
        },
        {
            "x": 13,
            "y": -3,
            "z": -1,
            "elements": [
                "modularmachinery:blockcasing@0"
            ]
        },
        {
            "x": -14,
            "y": 3,
            "z": 1,
            "elements": [
                "modularmachinery:blockcasing@0"
            ]
        },
        {
            "x": 3,
            "y": -3,
            "z": -1,
            "elements": [
                "modularmachinery:blockcasing@0"
            ]
        },
        {
            "x": -4,
            "y": 3,
            "z": 1,
            "elements": [
                "minecraft:end_stone@0"
            ]
        },
        {
            "x": 3,
            "y": 3,
            "z": 1,
            "elements": [
                "minecraft:end_stone@0"
            ]
        },
        {
            "x": -4,
            "y": -3,
            "z": -1,
            "elements": [
                "modularmachinery:blockcasing@0"
            ]
        },
        {
            "x": 13,
            "y": 3,
            "z": 1,
            "elements": [
                "modularmachinery:blockcasing@0"
            ]
        },
        {
            "x": -14,
            "y": -3,
            "z": -1,
            "elements": [
                "modularmachinery:blockcasing@0"
            ]
        },
        {
            "x": 13,
            "y": -4,
            "z": -1,
            "elements": [
                "modularmachinery:blockcasing@0"
            ]
        },
        {
            "x": -14,
            "y": 4,
            "z": 1,
            "elements": [
                "modularmachinery:blockcasing@0"
            ]
        },
        {
            "x": 3,
            "y": -4,
            "z": -1,
            "elements": [
                "modularmachinery:blockcasing@0"
            ]
        },
        {
            "x": -4,
            "y": 4,
            "z": 1,
            "elements": [
                "modularmachinery:blockcasing@0"
            ]
        },
        {
            "x": 3,
            "y": 4,
            "z": 1,
            "elements": [
                "modularmachinery:blockcasing@0"
            ]
        },
        {
            "x": -4,
            "y": -4,
            "z": -1,
            "elements": [
                "modularmachinery:blockcasing@0"
            ]
        },
        {
            "x": 13,
            "y": 4,
            "z": 1,
            "elements": [
                "modularmachinery:blockcasing@0"
            ]
        },
        {
            "x": -14,
            "y": -4,
            "z": -1,
            "elements": [
                "modularmachinery:blockcasing@0"
            ]
        },
        {
            "x": 13,
            "y": -5,
            "z": -1,
            "elements": [
                "astralsorcery:blockmarble@6"
            ]
        },
        {
            "x": -14,
            "y": 5,
            "z": 1,
            "elements": [
                "modularmachinery:blockcasing@0"
            ]
        },
        {
            "x": 3,
            "y": -5,
            "z": -1,
            "elements": [
                "astralsorcery:blockmarble@6"
            ]
        },
        {
            "x": -4,
            "y": 5,
            "z": 1,
            "elements": [
                "modularmachinery:blockcasing@0"
            ]
        },
        {
            "x": 3,
            "y": 5,
            "z": 1,
            "elements": [
                "modularmachinery:blockcasing@0"
            ]
        },
        {
            "x": -4,
            "y": -5,
            "z": -1,
            "elements": [
                "astralsorcery:blockmarble@6"
            ]
        },
        {
            "x": 13,
            "y": 5,
            "z": 1,
            "elements": [
                "modularmachinery:blockcasing@0"
            ]
        },
        {
            "x": -14,
            "y": -5,
            "z": -1,
            "elements": [
                "astralsorcery:blockmarble@6"
            ]
        },
        {
            "x": -14,
            "y": 6,
            "z": 1,
            "elements": [
                "astralsorcery:blockmarble@6"
            ]
        },
        {
            "x": 12,
            "y": -6,
            "z": -1,
            "elements": [
                "bloodmagic:demon_extras@1"
            ]
        },
        {
            "x": 4,
            "y": -6,
            "z": -1,
            "elements": [
                "bloodmagic:demon_extras@1"
            ]
        },
        {
            "x": -4,
            "y": 6,
            "z": 1,
            "elements": [
                "astralsorcery:blockmarble@6"
            ]
        },
        {
            "x": 3,
            "y": 6,
            "z": 1,
            "elements": [
                "astralsorcery:blockmarble@6"
            ]
        },
        {
            "x": -5,
            "y": -6,
            "z": -1,
            "elements": [
                "bloodmagic:demon_extras@1"
            ]
        },
        {
            "x": -13,
            "y": -6,
            "z": -1,
            "elements": [
                "bloodmagic:demon_extras@1"
            ]
        },
        {
            "x": 13,
            "y": 6,
            "z": 1,
            "elements": [
                "astralsorcery:blockmarble@6"
            ]
        },
        {
            "x": -14,
            "y": 7,
            "z": 1,
            "elements": [
                "bloodmagic:demon_extras@1"
            ]
        },
        {
            "x": 11,
            "y": -7,
            "z": -1,
            "elements": [
                "bloodmagic:demon_extras@0"
            ]
        },
        {
            "x": 5,
            "y": -7,
            "z": -1,
            "elements": [
                "bloodmagic:demon_extras@0"
            ]
        },
        {
            "x": -4,
            "y": 7,
            "z": 1,
            "elements": [
                "bloodmagic:demon_extras@1"
            ]
        },
        {
            "x": 3,
            "y": 7,
            "z": 1,
            "elements": [
                "bloodmagic:demon_extras@1"
            ]
        },
        {
            "x": -6,
            "y": -7,
            "z": -1,
            "elements": [
                "bloodmagic:demon_extras@0"
            ]
        },
        {
            "x": -12,
            "y": -7,
            "z": -1,
            "elements": [
                "bloodmagic:demon_extras@0"
            ]
        },
        {
            "x": 13,
            "y": 7,
            "z": 1,
            "elements": [
                "bloodmagic:demon_extras@1"
            ]
        },
        {
            "x": -13,
            "y": 8,
            "z": 1,
            "elements": [
                "bloodmagic:demon_extras@0"
            ]
        },
        {
            "x": 10,
            "y": -8,
            "z": -1,
            "elements": [
                "minecraft:purpur_block@0"
            ]
        },
        {
            "x": 9,
            "y": -8,
            "z": -1,
            "elements": [
                "minecraft:purpur_block@0"
            ]
        },
        {
            "x": 8,
            "y": -8,
            "z": -1,
            "elements": [
                "minecraft:purpur_block@0"
            ]
        },
        {
            "x": 7,
            "y": -8,
            "z": -1,
            "elements": [
                "minecraft:purpur_block@0"
            ]
        },
        {
            "x": 6,
            "y": -8,
            "z": -1,
            "elements": [
                "minecraft:purpur_block@0"
            ]
        },
        {
            "x": -5,
            "y": 8,
            "z": 1,
            "elements": [
                "bloodmagic:demon_extras@0"
            ]
        },
        {
            "x": 4,
            "y": 8,
            "z": 1,
            "elements": [
                "bloodmagic:demon_extras@0"
            ]
        },
        {
            "x": -7,
            "y": -8,
            "z": -1,
